[2018-02-10 21:15:37 +0000] [628] [INFO] Starting gunicorn 19.7.1
[2018-02-10 21:15:37 +0000] [628] [INFO] Listening at: unix:carwash.sock (628)
[2018-02-10 21:15:37 +0000] [628] [INFO] Using worker: sync
[2018-02-10 21:15:37 +0000] [631] [INFO] Booting worker with pid: 631
[2018-02-10 21:15:38 +0000] [632] [INFO] Booting worker with pid: 632
[2018-02-10 21:15:38 +0000] [633] [INFO] Booting worker with pid: 633
[2018-02-10 21:27:21 +0000] [633] [ERROR] Error handling request /dashboard/add-member
Traceback (most recent call last):
  File "/var/www/html/env/local/lib/python2.7/site-packages/gunicorn/workers/sync.py", line 135, in handle
    self.handle_request(listener, req, client, addr)
  File "/var/www/html/env/local/lib/python2.7/site-packages/gunicorn/workers/sync.py", line 176, in handle_request
    respiter = self.wsgi(environ, resp.start_response)
  File "/var/www/html/env/local/lib/python2.7/site-packages/flask/app.py", line 1997, in __call__
    return self.wsgi_app(environ, start_response)
  File "/var/www/html/env/local/lib/python2.7/site-packages/flask/app.py", line 1985, in wsgi_app
    response = self.handle_exception(e)
  File "/var/www/html/env/local/lib/python2.7/site-packages/flask/app.py", line 1540, in handle_exception
    reraise(exc_type, exc_value, tb)
  File "/var/www/html/env/local/lib/python2.7/site-packages/flask/app.py", line 1982, in wsgi_app
    response = self.full_dispatch_request()
  File "/var/www/html/env/local/lib/python2.7/site-packages/flask/app.py", line 1614, in full_dispatch_request
    rv = self.handle_user_exception(e)
  File "/var/www/html/env/local/lib/python2.7/site-packages/flask/app.py", line 1517, in handle_user_exception
    reraise(exc_type, exc_value, tb)
  File "/var/www/html/env/local/lib/python2.7/site-packages/flask/app.py", line 1612, in full_dispatch_request
    rv = self.dispatch_request()
  File "/var/www/html/env/local/lib/python2.7/site-packages/flask/app.py", line 1598, in dispatch_request
    return self.view_functions[rule.endpoint](**req.view_args)
  File "/var/www/html/env/local/lib/python2.7/site-packages/flask_login/utils.py", line 261, in decorated_view
    return func(*args, **kwargs)
  File "/var/www/html/c3car/app.py", line 628, in AddMember
    return render_template("user/add_member.html",form=form)
  File "/var/www/html/env/local/lib/python2.7/site-packages/flask/templating.py", line 134, in render_template
    context, ctx.app)
  File "/var/www/html/env/local/lib/python2.7/site-packages/flask/templating.py", line 116, in _render
    rv = template.render(context)
  File "/var/www/html/env/local/lib/python2.7/site-packages/jinja2/environment.py", line 1008, in render
    return self.environment.handle_exception(exc_info, True)
  File "/var/www/html/env/local/lib/python2.7/site-packages/jinja2/environment.py", line 780, in handle_exception
    reraise(exc_type, exc_value, tb)
  File "/var/www/html/c3car/templates/user/add_member.html", line 1, in top-level template code
    {% extends "layouts/dashboardtemplate.html" %}
  File "/var/www/html/c3car/templates/layouts/dashboardtemplate.html", line 310, in top-level template code
    {% block content %}
  File "/var/www/html/c3car/templates/user/add_member.html", line 55, in block "content"
    {{ render_field(form.location, class="form-control")}}
  File "/var/www/html/env/local/lib/python2.7/site-packages/jinja2/runtime.py", line 579, in _invoke
    rv = self._func(*arguments)
  File "/var/www/html/c3car/templates/includes/_formhelpers.html", line 3, in template
    <dd>{{ field(**kwargs)|safe }}
  File "/var/www/html/env/local/lib/python2.7/site-packages/wtforms/fields/core.py", line 153, in __call__
    return self.meta.render_field(self, kwargs)
  File "/var/www/html/env/local/lib/python2.7/site-packages/wtforms/meta.py", line 56, in render_field
    return field.widget(field, **render_kw)
  File "/var/www/html/env/local/lib/python2.7/site-packages/wtforms/widgets/core.py", line 287, in __call__
    for val, label, selected in field.iter_choices():
  File "/var/www/html/env/local/lib/python2.7/site-packages/wtforms/ext/sqlalchemy/fields.py", line 107, in iter_choices
    for pk, obj in self._get_object_list():
  File "/var/www/html/env/local/lib/python2.7/site-packages/wtforms/ext/sqlalchemy/fields.py", line 100, in _get_object_list
    self._object_list = list((text_type(get_pk(obj)), obj) for obj in query)
  File "/var/www/html/env/local/lib/python2.7/site-packages/wtforms/ext/sqlalchemy/fields.py", line 100, in <genexpr>
    self._object_list = list((text_type(get_pk(obj)), obj) for obj in query)
  File "/var/www/html/env/local/lib/python2.7/site-packages/wtforms/ext/sqlalchemy/fields.py", line 189, in get_pk_from_identity
    cls, key = identity_key(instance=obj)
ValueError: too many values to unpack
[2018-02-10 21:31:56 +0000] [631] [ERROR] Error handling request /dashboard/add-member
Traceback (most recent call last):
  File "/var/www/html/env/local/lib/python2.7/site-packages/gunicorn/workers/sync.py", line 135, in handle
    self.handle_request(listener, req, client, addr)
  File "/var/www/html/env/local/lib/python2.7/site-packages/gunicorn/workers/sync.py", line 176, in handle_request
    respiter = self.wsgi(environ, resp.start_response)
  File "/var/www/html/env/local/lib/python2.7/site-packages/flask/app.py", line 1997, in __call__
    return self.wsgi_app(environ, start_response)
  File "/var/www/html/env/local/lib/python2.7/site-packages/flask/app.py", line 1985, in wsgi_app
    response = self.handle_exception(e)
  File "/var/www/html/env/local/lib/python2.7/site-packages/flask/app.py", line 1540, in handle_exception
    reraise(exc_type, exc_value, tb)
  File "/var/www/html/env/local/lib/python2.7/site-packages/flask/app.py", line 1982, in wsgi_app
    response = self.full_dispatch_request()
  File "/var/www/html/env/local/lib/python2.7/site-packages/flask/app.py", line 1614, in full_dispatch_request
    rv = self.handle_user_exception(e)
  File "/var/www/html/env/local/lib/python2.7/site-packages/flask/app.py", line 1517, in handle_user_exception
    reraise(exc_type, exc_value, tb)
  File "/var/www/html/env/local/lib/python2.7/site-packages/flask/app.py", line 1612, in full_dispatch_request
    rv = self.dispatch_request()
  File "/var/www/html/env/local/lib/python2.7/site-packages/flask/app.py", line 1598, in dispatch_request
    return self.view_functions[rule.endpoint](**req.view_args)
  File "/var/www/html/env/local/lib/python2.7/site-packages/flask_login/utils.py", line 261, in decorated_view
    return func(*args, **kwargs)
  File "/var/www/html/c3car/app.py", line 628, in AddMember
    return render_template("user/add_member.html",form=form)
  File "/var/www/html/env/local/lib/python2.7/site-packages/flask/templating.py", line 134, in render_template
    context, ctx.app)
  File "/var/www/html/env/local/lib/python2.7/site-packages/flask/templating.py", line 116, in _render
    rv = template.render(context)
  File "/var/www/html/env/local/lib/python2.7/site-packages/jinja2/environment.py", line 1008, in render
    return self.environment.handle_exception(exc_info, True)
  File "/var/www/html/env/local/lib/python2.7/site-packages/jinja2/environment.py", line 780, in handle_exception
    reraise(exc_type, exc_value, tb)
  File "/var/www/html/c3car/templates/user/add_member.html", line 1, in top-level template code
    {% extends "layouts/dashboardtemplate.html" %}
  File "/var/www/html/c3car/templates/layouts/dashboardtemplate.html", line 310, in top-level template code
    {% block content %}
  File "/var/www/html/c3car/templates/user/add_member.html", line 55, in block "content"
    {{ render_field(form.location, class="form-control")}}
  File "/var/www/html/env/local/lib/python2.7/site-packages/jinja2/runtime.py", line 579, in _invoke
    rv = self._func(*arguments)
  File "/var/www/html/c3car/templates/includes/_formhelpers.html", line 3, in template
    <dd>{{ field(**kwargs)|safe }}
  File "/var/www/html/env/local/lib/python2.7/site-packages/wtforms/fields/core.py", line 153, in __call__
    return self.meta.render_field(self, kwargs)
  File "/var/www/html/env/local/lib/python2.7/site-packages/wtforms/meta.py", line 56, in render_field
    return field.widget(field, **render_kw)
  File "/var/www/html/env/local/lib/python2.7/site-packages/wtforms/widgets/core.py", line 287, in __call__
    for val, label, selected in field.iter_choices():
  File "/var/www/html/env/local/lib/python2.7/site-packages/wtforms/ext/sqlalchemy/fields.py", line 107, in iter_choices
    for pk, obj in self._get_object_list():
  File "/var/www/html/env/local/lib/python2.7/site-packages/wtforms/ext/sqlalchemy/fields.py", line 100, in _get_object_list
    self._object_list = list((text_type(get_pk(obj)), obj) for obj in query)
  File "/var/www/html/env/local/lib/python2.7/site-packages/wtforms/ext/sqlalchemy/fields.py", line 100, in <genexpr>
    self._object_list = list((text_type(get_pk(obj)), obj) for obj in query)
  File "/var/www/html/env/local/lib/python2.7/site-packages/wtforms/ext/sqlalchemy/fields.py", line 189, in get_pk_from_identity
    cls, key = identity_key(instance=obj)
ValueError: too many values to unpack
[2018-02-10 21:35:45 +0000] [631] [ERROR] Error handling request /dashboard/add-member
Traceback (most recent call last):
  File "/var/www/html/env/local/lib/python2.7/site-packages/gunicorn/workers/sync.py", line 135, in handle
    self.handle_request(listener, req, client, addr)
  File "/var/www/html/env/local/lib/python2.7/site-packages/gunicorn/workers/sync.py", line 176, in handle_request
    respiter = self.wsgi(environ, resp.start_response)
  File "/var/www/html/env/local/lib/python2.7/site-packages/flask/app.py", line 1997, in __call__
    return self.wsgi_app(environ, start_response)
  File "/var/www/html/env/local/lib/python2.7/site-packages/flask/app.py", line 1985, in wsgi_app
    response = self.handle_exception(e)
  File "/var/www/html/env/local/lib/python2.7/site-packages/flask/app.py", line 1540, in handle_exception
    reraise(exc_type, exc_value, tb)
  File "/var/www/html/env/local/lib/python2.7/site-packages/flask/app.py", line 1982, in wsgi_app
    response = self.full_dispatch_request()
  File "/var/www/html/env/local/lib/python2.7/site-packages/flask/app.py", line 1614, in full_dispatch_request
    rv = self.handle_user_exception(e)
  File "/var/www/html/env/local/lib/python2.7/site-packages/flask/app.py", line 1517, in handle_user_exception
    reraise(exc_type, exc_value, tb)
  File "/var/www/html/env/local/lib/python2.7/site-packages/flask/app.py", line 1612, in full_dispatch_request
    rv = self.dispatch_request()
  File "/var/www/html/env/local/lib/python2.7/site-packages/flask/app.py", line 1598, in dispatch_request
    return self.view_functions[rule.endpoint](**req.view_args)
  File "/var/www/html/env/local/lib/python2.7/site-packages/flask_login/utils.py", line 261, in decorated_view
    return func(*args, **kwargs)
  File "/var/www/html/c3car/app.py", line 628, in AddMember
    return render_template("user/add_member.html",form=form)
  File "/var/www/html/env/local/lib/python2.7/site-packages/flask/templating.py", line 134, in render_template
    context, ctx.app)
  File "/var/www/html/env/local/lib/python2.7/site-packages/flask/templating.py", line 116, in _render
    rv = template.render(context)
  File "/var/www/html/env/local/lib/python2.7/site-packages/jinja2/environment.py", line 1008, in render
    return self.environment.handle_exception(exc_info, True)
  File "/var/www/html/env/local/lib/python2.7/site-packages/jinja2/environment.py", line 780, in handle_exception
    reraise(exc_type, exc_value, tb)
  File "/var/www/html/c3car/templates/user/add_member.html", line 1, in top-level template code
    {% extends "layouts/dashboardtemplate.html" %}
  File "/var/www/html/c3car/templates/layouts/dashboardtemplate.html", line 310, in top-level template code
    {% block content %}
  File "/var/www/html/c3car/templates/user/add_member.html", line 55, in block "content"
    {{ render_field(form.location, class="form-control")}}
  File "/var/www/html/env/local/lib/python2.7/site-packages/jinja2/runtime.py", line 579, in _invoke
    rv = self._func(*arguments)
  File "/var/www/html/c3car/templates/includes/_formhelpers.html", line 3, in template
    <dd>{{ field(**kwargs)|safe }}
  File "/var/www/html/env/local/lib/python2.7/site-packages/wtforms/fields/core.py", line 153, in __call__
    return self.meta.render_field(self, kwargs)
  File "/var/www/html/env/local/lib/python2.7/site-packages/wtforms/meta.py", line 56, in render_field
    return field.widget(field, **render_kw)
  File "/var/www/html/env/local/lib/python2.7/site-packages/wtforms/widgets/core.py", line 287, in __call__
    for val, label, selected in field.iter_choices():
  File "/var/www/html/env/local/lib/python2.7/site-packages/wtforms/ext/sqlalchemy/fields.py", line 107, in iter_choices
    for pk, obj in self._get_object_list():
  File "/var/www/html/env/local/lib/python2.7/site-packages/wtforms/ext/sqlalchemy/fields.py", line 100, in _get_object_list
    self._object_list = list((text_type(get_pk(obj)), obj) for obj in query)
  File "/var/www/html/env/local/lib/python2.7/site-packages/wtforms/ext/sqlalchemy/fields.py", line 100, in <genexpr>
    self._object_list = list((text_type(get_pk(obj)), obj) for obj in query)
  File "/var/www/html/env/local/lib/python2.7/site-packages/wtforms/ext/sqlalchemy/fields.py", line 189, in get_pk_from_identity
    cls, key = identity_key(instance=obj)
ValueError: too many values to unpack
[2018-02-10 21:51:53 +0000] [633] [ERROR] Error handling request /dashboard/add-member
Traceback (most recent call last):
  File "/var/www/html/env/local/lib/python2.7/site-packages/gunicorn/workers/sync.py", line 135, in handle
    self.handle_request(listener, req, client, addr)
  File "/var/www/html/env/local/lib/python2.7/site-packages/gunicorn/workers/sync.py", line 176, in handle_request
    respiter = self.wsgi(environ, resp.start_response)
  File "/var/www/html/env/local/lib/python2.7/site-packages/flask/app.py", line 1997, in __call__
    return self.wsgi_app(environ, start_response)
  File "/var/www/html/env/local/lib/python2.7/site-packages/flask/app.py", line 1985, in wsgi_app
    response = self.handle_exception(e)
  File "/var/www/html/env/local/lib/python2.7/site-packages/flask/app.py", line 1540, in handle_exception
    reraise(exc_type, exc_value, tb)
  File "/var/www/html/env/local/lib/python2.7/site-packages/flask/app.py", line 1982, in wsgi_app
    response = self.full_dispatch_request()
  File "/var/www/html/env/local/lib/python2.7/site-packages/flask/app.py", line 1614, in full_dispatch_request
    rv = self.handle_user_exception(e)
  File "/var/www/html/env/local/lib/python2.7/site-packages/flask/app.py", line 1517, in handle_user_exception
    reraise(exc_type, exc_value, tb)
  File "/var/www/html/env/local/lib/python2.7/site-packages/flask/app.py", line 1612, in full_dispatch_request
    rv = self.dispatch_request()
  File "/var/www/html/env/local/lib/python2.7/site-packages/flask/app.py", line 1598, in dispatch_request
    return self.view_functions[rule.endpoint](**req.view_args)
  File "/var/www/html/env/local/lib/python2.7/site-packages/flask_login/utils.py", line 261, in decorated_view
    return func(*args, **kwargs)
  File "/var/www/html/c3car/app.py", line 628, in AddMember
    return render_template("user/add_member.html",form=form)
  File "/var/www/html/env/local/lib/python2.7/site-packages/flask/templating.py", line 134, in render_template
    context, ctx.app)
  File "/var/www/html/env/local/lib/python2.7/site-packages/flask/templating.py", line 116, in _render
    rv = template.render(context)
  File "/var/www/html/env/local/lib/python2.7/site-packages/jinja2/environment.py", line 1008, in render
    return self.environment.handle_exception(exc_info, True)
  File "/var/www/html/env/local/lib/python2.7/site-packages/jinja2/environment.py", line 780, in handle_exception
    reraise(exc_type, exc_value, tb)
  File "/var/www/html/c3car/templates/user/add_member.html", line 1, in top-level template code
    {% extends "layouts/dashboardtemplate.html" %}
  File "/var/www/html/c3car/templates/layouts/dashboardtemplate.html", line 310, in top-level template code
    {% block content %}
  File "/var/www/html/c3car/templates/user/add_member.html", line 55, in block "content"
    {{ render_field(form.location, class="form-control")}}
  File "/var/www/html/env/local/lib/python2.7/site-packages/jinja2/runtime.py", line 579, in _invoke
    rv = self._func(*arguments)
  File "/var/www/html/c3car/templates/includes/_formhelpers.html", line 3, in template
    <dd>{{ field(**kwargs)|safe }}
  File "/var/www/html/env/local/lib/python2.7/site-packages/wtforms/fields/core.py", line 153, in __call__
    return self.meta.render_field(self, kwargs)
  File "/var/www/html/env/local/lib/python2.7/site-packages/wtforms/meta.py", line 56, in render_field
    return field.widget(field, **render_kw)
  File "/var/www/html/env/local/lib/python2.7/site-packages/wtforms/widgets/core.py", line 287, in __call__
    for val, label, selected in field.iter_choices():
  File "/var/www/html/env/local/lib/python2.7/site-packages/wtforms/ext/sqlalchemy/fields.py", line 107, in iter_choices
    for pk, obj in self._get_object_list():
  File "/var/www/html/env/local/lib/python2.7/site-packages/wtforms/ext/sqlalchemy/fields.py", line 100, in _get_object_list
    self._object_list = list((text_type(get_pk(obj)), obj) for obj in query)
  File "/var/www/html/env/local/lib/python2.7/site-packages/wtforms/ext/sqlalchemy/fields.py", line 100, in <genexpr>
    self._object_list = list((text_type(get_pk(obj)), obj) for obj in query)
  File "/var/www/html/env/local/lib/python2.7/site-packages/wtforms/ext/sqlalchemy/fields.py", line 189, in get_pk_from_identity
    cls, key = identity_key(instance=obj)
ValueError: too many values to unpack
[2018-02-10 21:51:58 +0000] [631] [ERROR] Error handling request /dashboard/add-member
Traceback (most recent call last):
  File "/var/www/html/env/local/lib/python2.7/site-packages/gunicorn/workers/sync.py", line 135, in handle
    self.handle_request(listener, req, client, addr)
  File "/var/www/html/env/local/lib/python2.7/site-packages/gunicorn/workers/sync.py", line 176, in handle_request
    respiter = self.wsgi(environ, resp.start_response)
  File "/var/www/html/env/local/lib/python2.7/site-packages/flask/app.py", line 1997, in __call__
    return self.wsgi_app(environ, start_response)
  File "/var/www/html/env/local/lib/python2.7/site-packages/flask/app.py", line 1985, in wsgi_app
    response = self.handle_exception(e)
  File "/var/www/html/env/local/lib/python2.7/site-packages/flask/app.py", line 1540, in handle_exception
    reraise(exc_type, exc_value, tb)
  File "/var/www/html/env/local/lib/python2.7/site-packages/flask/app.py", line 1982, in wsgi_app
    response = self.full_dispatch_request()
  File "/var/www/html/env/local/lib/python2.7/site-packages/flask/app.py", line 1614, in full_dispatch_request
    rv = self.handle_user_exception(e)
  File "/var/www/html/env/local/lib/python2.7/site-packages/flask/app.py", line 1517, in handle_user_exception
    reraise(exc_type, exc_value, tb)
  File "/var/www/html/env/local/lib/python2.7/site-packages/flask/app.py", line 1612, in full_dispatch_request
    rv = self.dispatch_request()
  File "/var/www/html/env/local/lib/python2.7/site-packages/flask/app.py", line 1598, in dispatch_request
    return self.view_functions[rule.endpoint](**req.view_args)
  File "/var/www/html/env/local/lib/python2.7/site-packages/flask_login/utils.py", line 261, in decorated_view
    return func(*args, **kwargs)
  File "/var/www/html/c3car/app.py", line 628, in AddMember
    return render_template("user/add_member.html",form=form)
  File "/var/www/html/env/local/lib/python2.7/site-packages/flask/templating.py", line 134, in render_template
    context, ctx.app)
  File "/var/www/html/env/local/lib/python2.7/site-packages/flask/templating.py", line 116, in _render
    rv = template.render(context)
  File "/var/www/html/env/local/lib/python2.7/site-packages/jinja2/environment.py", line 1008, in render
    return self.environment.handle_exception(exc_info, True)
  File "/var/www/html/env/local/lib/python2.7/site-packages/jinja2/environment.py", line 780, in handle_exception
    reraise(exc_type, exc_value, tb)
  File "/var/www/html/c3car/templates/user/add_member.html", line 1, in top-level template code
    {% extends "layouts/dashboardtemplate.html" %}
  File "/var/www/html/c3car/templates/layouts/dashboardtemplate.html", line 310, in top-level template code
    {% block content %}
  File "/var/www/html/c3car/templates/user/add_member.html", line 55, in block "content"
    {{ render_field(form.location, class="form-control")}}
  File "/var/www/html/env/local/lib/python2.7/site-packages/jinja2/runtime.py", line 579, in _invoke
    rv = self._func(*arguments)
  File "/var/www/html/c3car/templates/includes/_formhelpers.html", line 3, in template
    <dd>{{ field(**kwargs)|safe }}
  File "/var/www/html/env/local/lib/python2.7/site-packages/wtforms/fields/core.py", line 153, in __call__
    return self.meta.render_field(self, kwargs)
  File "/var/www/html/env/local/lib/python2.7/site-packages/wtforms/meta.py", line 56, in render_field
    return field.widget(field, **render_kw)
  File "/var/www/html/env/local/lib/python2.7/site-packages/wtforms/widgets/core.py", line 287, in __call__
    for val, label, selected in field.iter_choices():
  File "/var/www/html/env/local/lib/python2.7/site-packages/wtforms/ext/sqlalchemy/fields.py", line 107, in iter_choices
    for pk, obj in self._get_object_list():
  File "/var/www/html/env/local/lib/python2.7/site-packages/wtforms/ext/sqlalchemy/fields.py", line 100, in _get_object_list
    self._object_list = list((text_type(get_pk(obj)), obj) for obj in query)
  File "/var/www/html/env/local/lib/python2.7/site-packages/wtforms/ext/sqlalchemy/fields.py", line 100, in <genexpr>
    self._object_list = list((text_type(get_pk(obj)), obj) for obj in query)
  File "/var/www/html/env/local/lib/python2.7/site-packages/wtforms/ext/sqlalchemy/fields.py", line 189, in get_pk_from_identity
    cls, key = identity_key(instance=obj)
ValueError: too many values to unpack
[2018-02-10 21:52:10 +0000] [631] [ERROR] Error handling request /dashboard/admin-booking/regular
Traceback (most recent call last):
  File "/var/www/html/env/local/lib/python2.7/site-packages/gunicorn/workers/sync.py", line 135, in handle
    self.handle_request(listener, req, client, addr)
  File "/var/www/html/env/local/lib/python2.7/site-packages/gunicorn/workers/sync.py", line 176, in handle_request
    respiter = self.wsgi(environ, resp.start_response)
  File "/var/www/html/env/local/lib/python2.7/site-packages/flask/app.py", line 1997, in __call__
    return self.wsgi_app(environ, start_response)
  File "/var/www/html/env/local/lib/python2.7/site-packages/flask/app.py", line 1985, in wsgi_app
    response = self.handle_exception(e)
  File "/var/www/html/env/local/lib/python2.7/site-packages/flask/app.py", line 1540, in handle_exception
    reraise(exc_type, exc_value, tb)
  File "/var/www/html/env/local/lib/python2.7/site-packages/flask/app.py", line 1982, in wsgi_app
    response = self.full_dispatch_request()
  File "/var/www/html/env/local/lib/python2.7/site-packages/flask/app.py", line 1614, in full_dispatch_request
    rv = self.handle_user_exception(e)
  File "/var/www/html/env/local/lib/python2.7/site-packages/flask/app.py", line 1517, in handle_user_exception
    reraise(exc_type, exc_value, tb)
  File "/var/www/html/env/local/lib/python2.7/site-packages/flask/app.py", line 1612, in full_dispatch_request
    rv = self.dispatch_request()
  File "/var/www/html/env/local/lib/python2.7/site-packages/flask/app.py", line 1598, in dispatch_request
    return self.view_functions[rule.endpoint](**req.view_args)
  File "/var/www/html/env/local/lib/python2.7/site-packages/flask_login/utils.py", line 261, in decorated_view
    return func(*args, **kwargs)
  File "/var/www/html/c3car/app.py", line 749, in AdminBookingRegular
    return render_template("user/booking.html",form=form)
  File "/var/www/html/env/local/lib/python2.7/site-packages/flask/templating.py", line 134, in render_template
    context, ctx.app)
  File "/var/www/html/env/local/lib/python2.7/site-packages/flask/templating.py", line 116, in _render
    rv = template.render(context)
  File "/var/www/html/env/local/lib/python2.7/site-packages/jinja2/environment.py", line 1008, in render
    return self.environment.handle_exception(exc_info, True)
  File "/var/www/html/env/local/lib/python2.7/site-packages/jinja2/environment.py", line 780, in handle_exception
    reraise(exc_type, exc_value, tb)
  File "/var/www/html/c3car/templates/user/booking.html", line 1, in top-level template code
    {% extends "layouts/dashboardtemplate.html" %}
  File "/var/www/html/c3car/templates/layouts/dashboardtemplate.html", line 310, in top-level template code
    {% block content %}
  File "/var/www/html/c3car/templates/user/booking.html", line 38, in block "content"
    {{ render_field(form.paket, class="form-control")}}
  File "/var/www/html/env/local/lib/python2.7/site-packages/jinja2/runtime.py", line 579, in _invoke
    rv = self._func(*arguments)
  File "/var/www/html/c3car/templates/includes/_formhelpers.html", line 3, in template
    <dd>{{ field(**kwargs)|safe }}
  File "/var/www/html/env/local/lib/python2.7/site-packages/wtforms/fields/core.py", line 153, in __call__
    return self.meta.render_field(self, kwargs)
  File "/var/www/html/env/local/lib/python2.7/site-packages/wtforms/meta.py", line 56, in render_field
    return field.widget(field, **render_kw)
  File "/var/www/html/env/local/lib/python2.7/site-packages/wtforms/widgets/core.py", line 287, in __call__
    for val, label, selected in field.iter_choices():
  File "/var/www/html/env/local/lib/python2.7/site-packages/wtforms/ext/sqlalchemy/fields.py", line 107, in iter_choices
    for pk, obj in self._get_object_list():
  File "/var/www/html/env/local/lib/python2.7/site-packages/wtforms/ext/sqlalchemy/fields.py", line 100, in _get_object_list
    self._object_list = list((text_type(get_pk(obj)), obj) for obj in query)
  File "/var/www/html/env/local/lib/python2.7/site-packages/wtforms/ext/sqlalchemy/fields.py", line 100, in <genexpr>
    self._object_list = list((text_type(get_pk(obj)), obj) for obj in query)
  File "/var/www/html/env/local/lib/python2.7/site-packages/wtforms/ext/sqlalchemy/fields.py", line 189, in get_pk_from_identity
    cls, key = identity_key(instance=obj)
ValueError: too many values to unpack
[2018-02-10 21:57:28 +0000] [633] [INFO] Worker exiting (pid: 633)
[2018-02-10 21:57:28 +0000] [632] [INFO] Worker exiting (pid: 632)
[2018-02-10 21:57:28 +0000] [631] [INFO] Worker exiting (pid: 631)
[2018-02-10 21:57:28 +0000] [628] [INFO] Handling signal: term
[2018-02-10 21:57:28 +0000] [628] [INFO] Shutting down: Master
[2018-02-10 21:58:00 +0000] [299] [INFO] Starting gunicorn 19.7.1
[2018-02-10 21:58:00 +0000] [299] [INFO] Listening at: unix:carwash.sock (299)
[2018-02-10 21:58:00 +0000] [299] [INFO] Using worker: sync
[2018-02-10 21:58:00 +0000] [401] [INFO] Booting worker with pid: 401
[2018-02-10 21:58:00 +0000] [403] [INFO] Booting worker with pid: 403
[2018-02-10 21:58:00 +0000] [404] [INFO] Booting worker with pid: 404
[2018-02-10 22:02:11 +0000] [404] [ERROR] Socket error processing request.
Traceback (most recent call last):
  File "/var/www/html/env/local/lib/python2.7/site-packages/gunicorn/workers/sync.py", line 135, in handle
    self.handle_request(listener, req, client, addr)
  File "/var/www/html/env/local/lib/python2.7/site-packages/gunicorn/workers/sync.py", line 191, in handle_request
    six.reraise(*sys.exc_info())
  File "/var/www/html/env/local/lib/python2.7/site-packages/gunicorn/workers/sync.py", line 176, in handle_request
    respiter = self.wsgi(environ, resp.start_response)
  File "/var/www/html/env/local/lib/python2.7/site-packages/flask/app.py", line 1997, in __call__
    return self.wsgi_app(environ, start_response)
  File "/var/www/html/env/local/lib/python2.7/site-packages/flask/app.py", line 1985, in wsgi_app
    response = self.handle_exception(e)
  File "/var/www/html/env/local/lib/python2.7/site-packages/flask/app.py", line 1540, in handle_exception
    reraise(exc_type, exc_value, tb)
  File "/var/www/html/env/local/lib/python2.7/site-packages/flask/app.py", line 1982, in wsgi_app
    response = self.full_dispatch_request()
  File "/var/www/html/env/local/lib/python2.7/site-packages/flask/app.py", line 1614, in full_dispatch_request
    rv = self.handle_user_exception(e)
  File "/var/www/html/env/local/lib/python2.7/site-packages/flask/app.py", line 1517, in handle_user_exception
    reraise(exc_type, exc_value, tb)
  File "/var/www/html/env/local/lib/python2.7/site-packages/flask/app.py", line 1612, in full_dispatch_request
    rv = self.dispatch_request()
  File "/var/www/html/env/local/lib/python2.7/site-packages/flask/app.py", line 1598, in dispatch_request
    return self.view_functions[rule.endpoint](**req.view_args)
  File "/var/www/html/env/local/lib/python2.7/site-packages/flask_login/utils.py", line 261, in decorated_view
    return func(*args, **kwargs)
  File "/var/www/html/c3car/app.py", line 1065, in UserInvoice
    pdf = pdfkit.from_string(rendered, False,css=css)
  File "/var/www/html/env/local/lib/python2.7/site-packages/pdfkit/api.py", line 70, in from_string
    configuration=configuration, cover_first=cover_first)
  File "/var/www/html/env/local/lib/python2.7/site-packages/pdfkit/pdfkit.py", line 42, in __init__
    self.configuration = (Configuration() if configuration is None
  File "/var/www/html/env/local/lib/python2.7/site-packages/pdfkit/configuration.py", line 18, in __init__
    ['which', 'wkhtmltopdf'], stdout=subprocess.PIPE).communicate()[0].strip()
  File "/usr/lib/python2.7/subprocess.py", line 711, in __init__
    errread, errwrite)
  File "/usr/lib/python2.7/subprocess.py", line 1343, in _execute_child
    raise child_exception
OSError: [Errno 2] No such file or directory
[2018-02-10 22:10:39 +0000] [404] [ERROR] Socket error processing request.
Traceback (most recent call last):
  File "/var/www/html/env/local/lib/python2.7/site-packages/gunicorn/workers/sync.py", line 135, in handle
    self.handle_request(listener, req, client, addr)
  File "/var/www/html/env/local/lib/python2.7/site-packages/gunicorn/workers/sync.py", line 191, in handle_request
    six.reraise(*sys.exc_info())
  File "/var/www/html/env/local/lib/python2.7/site-packages/gunicorn/workers/sync.py", line 176, in handle_request
    respiter = self.wsgi(environ, resp.start_response)
  File "/var/www/html/env/local/lib/python2.7/site-packages/flask/app.py", line 1997, in __call__
    return self.wsgi_app(environ, start_response)
  File "/var/www/html/env/local/lib/python2.7/site-packages/flask/app.py", line 1985, in wsgi_app
    response = self.handle_exception(e)
  File "/var/www/html/env/local/lib/python2.7/site-packages/flask/app.py", line 1540, in handle_exception
    reraise(exc_type, exc_value, tb)
  File "/var/www/html/env/local/lib/python2.7/site-packages/flask/app.py", line 1982, in wsgi_app
    response = self.full_dispatch_request()
  File "/var/www/html/env/local/lib/python2.7/site-packages/flask/app.py", line 1614, in full_dispatch_request
    rv = self.handle_user_exception(e)
  File "/var/www/html/env/local/lib/python2.7/site-packages/flask/app.py", line 1517, in handle_user_exception
    reraise(exc_type, exc_value, tb)
  File "/var/www/html/env/local/lib/python2.7/site-packages/flask/app.py", line 1612, in full_dispatch_request
    rv = self.dispatch_request()
  File "/var/www/html/env/local/lib/python2.7/site-packages/flask/app.py", line 1598, in dispatch_request
    return self.view_functions[rule.endpoint](**req.view_args)
  File "/var/www/html/env/local/lib/python2.7/site-packages/flask_login/utils.py", line 261, in decorated_view
    return func(*args, **kwargs)
  File "/var/www/html/c3car/app.py", line 1114, in UserInvoice
    pdf = pdfkit.from_string(rendered, False,css=css)
  File "/var/www/html/env/local/lib/python2.7/site-packages/pdfkit/api.py", line 70, in from_string
    configuration=configuration, cover_first=cover_first)
  File "/var/www/html/env/local/lib/python2.7/site-packages/pdfkit/pdfkit.py", line 42, in __init__
    self.configuration = (Configuration() if configuration is None
  File "/var/www/html/env/local/lib/python2.7/site-packages/pdfkit/configuration.py", line 18, in __init__
    ['which', 'wkhtmltopdf'], stdout=subprocess.PIPE).communicate()[0].strip()
  File "/usr/lib/python2.7/subprocess.py", line 711, in __init__
    errread, errwrite)
  File "/usr/lib/python2.7/subprocess.py", line 1343, in _execute_child
    raise child_exception
OSError: [Errno 2] No such file or directory
[2018-02-10 22:42:58 +0000] [403] [INFO] Worker exiting (pid: 403)
[2018-02-10 22:42:58 +0000] [404] [INFO] Worker exiting (pid: 404)
[2018-02-10 22:42:58 +0000] [401] [INFO] Worker exiting (pid: 401)
[2018-02-10 22:42:58 +0000] [299] [INFO] Handling signal: term
[2018-02-10 22:42:58 +0000] [299] [INFO] Shutting down: Master
[2018-02-10 22:43:32 +0000] [312] [INFO] Starting gunicorn 19.7.1
[2018-02-10 22:43:32 +0000] [312] [INFO] Listening at: unix:carwash.sock (312)
[2018-02-10 22:43:32 +0000] [312] [INFO] Using worker: sync
[2018-02-10 22:43:32 +0000] [401] [INFO] Booting worker with pid: 401
[2018-02-10 22:43:32 +0000] [402] [INFO] Booting worker with pid: 402
[2018-02-10 22:43:32 +0000] [404] [INFO] Booting worker with pid: 404
[2018-02-10 23:04:10 +0000] [401] [INFO] Worker exiting (pid: 401)
[2018-02-10 23:04:10 +0000] [402] [INFO] Worker exiting (pid: 402)
[2018-02-10 23:04:10 +0000] [404] [INFO] Worker exiting (pid: 404)
[2018-02-10 23:04:10 +0000] [312] [INFO] Handling signal: term
[2018-02-10 23:04:10 +0000] [312] [INFO] Shutting down: Master
[2018-02-10 23:04:42 +0000] [306] [INFO] Starting gunicorn 19.7.1
[2018-02-10 23:04:42 +0000] [306] [INFO] Listening at: unix:carwash.sock (306)
[2018-02-10 23:04:42 +0000] [306] [INFO] Using worker: sync
[2018-02-10 23:04:43 +0000] [410] [INFO] Booting worker with pid: 410
[2018-02-10 23:04:43 +0000] [409] [INFO] Booting worker with pid: 409
[2018-02-10 23:04:43 +0000] [412] [INFO] Booting worker with pid: 412
[2018-02-10 23:05:16 +0000] [410] [ERROR] Socket error processing request.
Traceback (most recent call last):
  File "/var/www/html/env/local/lib/python2.7/site-packages/gunicorn/workers/sync.py", line 135, in handle
    self.handle_request(listener, req, client, addr)
  File "/var/www/html/env/local/lib/python2.7/site-packages/gunicorn/workers/sync.py", line 191, in handle_request
    six.reraise(*sys.exc_info())
  File "/var/www/html/env/local/lib/python2.7/site-packages/gunicorn/workers/sync.py", line 176, in handle_request
    respiter = self.wsgi(environ, resp.start_response)
  File "/var/www/html/env/local/lib/python2.7/site-packages/flask/app.py", line 1997, in __call__
    return self.wsgi_app(environ, start_response)
  File "/var/www/html/env/local/lib/python2.7/site-packages/flask/app.py", line 1985, in wsgi_app
    response = self.handle_exception(e)
  File "/var/www/html/env/local/lib/python2.7/site-packages/flask/app.py", line 1540, in handle_exception
    reraise(exc_type, exc_value, tb)
  File "/var/www/html/env/local/lib/python2.7/site-packages/flask/app.py", line 1982, in wsgi_app
    response = self.full_dispatch_request()
  File "/var/www/html/env/local/lib/python2.7/site-packages/flask/app.py", line 1614, in full_dispatch_request
    rv = self.handle_user_exception(e)
  File "/var/www/html/env/local/lib/python2.7/site-packages/flask/app.py", line 1517, in handle_user_exception
    reraise(exc_type, exc_value, tb)
  File "/var/www/html/env/local/lib/python2.7/site-packages/flask/app.py", line 1612, in full_dispatch_request
    rv = self.dispatch_request()
  File "/var/www/html/env/local/lib/python2.7/site-packages/flask/app.py", line 1598, in dispatch_request
    return self.view_functions[rule.endpoint](**req.view_args)
  File "/var/www/html/env/local/lib/python2.7/site-packages/flask_login/utils.py", line 261, in decorated_view
    return func(*args, **kwargs)
  File "/var/www/html/c3car/app.py", line 1114, in UserInvoice
    pdf = pdfkit.from_string(rendered, False,css=css)
  File "/var/www/html/env/local/lib/python2.7/site-packages/pdfkit/api.py", line 70, in from_string
    configuration=configuration, cover_first=cover_first)
  File "/var/www/html/env/local/lib/python2.7/site-packages/pdfkit/pdfkit.py", line 42, in __init__
    self.configuration = (Configuration() if configuration is None
  File "/var/www/html/env/local/lib/python2.7/site-packages/pdfkit/configuration.py", line 18, in __init__
    ['which', 'wkhtmltopdf'], stdout=subprocess.PIPE).communicate()[0].strip()
  File "/usr/lib/python2.7/subprocess.py", line 711, in __init__
    errread, errwrite)
  File "/usr/lib/python2.7/subprocess.py", line 1343, in _execute_child
    raise child_exception
OSError: [Errno 2] No such file or directory
[2018-02-10 23:09:16 +0000] [409] [ERROR] Socket error processing request.
Traceback (most recent call last):
  File "/var/www/html/env/local/lib/python2.7/site-packages/gunicorn/workers/sync.py", line 135, in handle
    self.handle_request(listener, req, client, addr)
  File "/var/www/html/env/local/lib/python2.7/site-packages/gunicorn/workers/sync.py", line 191, in handle_request
    six.reraise(*sys.exc_info())
  File "/var/www/html/env/local/lib/python2.7/site-packages/gunicorn/workers/sync.py", line 176, in handle_request
    respiter = self.wsgi(environ, resp.start_response)
  File "/var/www/html/env/local/lib/python2.7/site-packages/flask/app.py", line 1997, in __call__
    return self.wsgi_app(environ, start_response)
  File "/var/www/html/env/local/lib/python2.7/site-packages/flask/app.py", line 1985, in wsgi_app
    response = self.handle_exception(e)
  File "/var/www/html/env/local/lib/python2.7/site-packages/flask/app.py", line 1540, in handle_exception
    reraise(exc_type, exc_value, tb)
  File "/var/www/html/env/local/lib/python2.7/site-packages/flask/app.py", line 1982, in wsgi_app
    response = self.full_dispatch_request()
  File "/var/www/html/env/local/lib/python2.7/site-packages/flask/app.py", line 1614, in full_dispatch_request
    rv = self.handle_user_exception(e)
  File "/var/www/html/env/local/lib/python2.7/site-packages/flask/app.py", line 1517, in handle_user_exception
    reraise(exc_type, exc_value, tb)
  File "/var/www/html/env/local/lib/python2.7/site-packages/flask/app.py", line 1612, in full_dispatch_request
    rv = self.dispatch_request()
  File "/var/www/html/env/local/lib/python2.7/site-packages/flask/app.py", line 1598, in dispatch_request
    return self.view_functions[rule.endpoint](**req.view_args)
  File "/var/www/html/env/local/lib/python2.7/site-packages/flask_login/utils.py", line 261, in decorated_view
    return func(*args, **kwargs)
  File "/var/www/html/c3car/app.py", line 1114, in UserInvoice
    pdf = pdfkit.from_string(rendered, False,css=css)
  File "/var/www/html/env/local/lib/python2.7/site-packages/pdfkit/api.py", line 70, in from_string
    configuration=configuration, cover_first=cover_first)
  File "/var/www/html/env/local/lib/python2.7/site-packages/pdfkit/pdfkit.py", line 42, in __init__
    self.configuration = (Configuration() if configuration is None
  File "/var/www/html/env/local/lib/python2.7/site-packages/pdfkit/configuration.py", line 18, in __init__
    ['which', 'wkhtmltopdf'], stdout=subprocess.PIPE).communicate()[0].strip()
  File "/usr/lib/python2.7/subprocess.py", line 711, in __init__
    errread, errwrite)
  File "/usr/lib/python2.7/subprocess.py", line 1343, in _execute_child
    raise child_exception
OSError: [Errno 2] No such file or directory
[2018-02-28 10:01:11 +0000] [314] [INFO] Starting gunicorn 19.7.1
[2018-02-28 10:01:11 +0000] [314] [INFO] Listening at: unix:carwash.sock (314)
[2018-02-28 10:01:11 +0000] [314] [INFO] Using worker: sync
[2018-02-28 10:01:11 +0000] [391] [INFO] Booting worker with pid: 391
[2018-02-28 10:01:11 +0000] [394] [INFO] Booting worker with pid: 394
[2018-02-28 10:01:11 +0000] [395] [INFO] Booting worker with pid: 395
[2018-02-28 10:12:21 +0000] [314] [INFO] Handling signal: term
[2018-02-28 10:12:21 +0000] [395] [INFO] Worker exiting (pid: 395)
[2018-02-28 10:12:21 +0000] [394] [INFO] Worker exiting (pid: 394)
[2018-02-28 10:12:21 +0000] [391] [INFO] Worker exiting (pid: 391)
[2018-02-28 10:12:22 +0000] [314] [INFO] Shutting down: Master
[2018-02-28 10:12:34 +0000] [311] [INFO] Starting gunicorn 19.7.1
[2018-02-28 10:12:34 +0000] [311] [INFO] Listening at: unix:carwash.sock (311)
[2018-02-28 10:12:34 +0000] [311] [INFO] Using worker: sync
[2018-02-28 10:12:34 +0000] [390] [INFO] Booting worker with pid: 390
[2018-02-28 10:12:34 +0000] [391] [INFO] Booting worker with pid: 391
[2018-02-28 10:12:34 +0000] [394] [INFO] Booting worker with pid: 394
[2018-02-28 23:37:13 +0000] [311] [INFO] Handling signal: term
[2018-02-28 23:37:13 +0000] [391] [INFO] Worker exiting (pid: 391)
[2018-02-28 23:37:13 +0000] [394] [INFO] Worker exiting (pid: 394)
[2018-02-28 23:37:13 +0000] [390] [INFO] Worker exiting (pid: 390)
[2018-02-28 23:37:13 +0000] [311] [INFO] Shutting down: Master
[2018-02-28 23:37:36 +0000] [311] [INFO] Starting gunicorn 19.7.1
[2018-02-28 23:37:36 +0000] [311] [INFO] Listening at: unix:carwash.sock (311)
[2018-02-28 23:37:36 +0000] [311] [INFO] Using worker: sync
[2018-02-28 23:37:36 +0000] [390] [INFO] Booting worker with pid: 390
[2018-02-28 23:37:36 +0000] [393] [INFO] Booting worker with pid: 393
[2018-02-28 23:37:36 +0000] [394] [INFO] Booting worker with pid: 394
[2018-03-01 02:24:33 +0000] [390] [INFO] Worker exiting (pid: 390)
[2018-03-01 02:24:33 +0000] [394] [INFO] Worker exiting (pid: 394)
[2018-03-01 02:24:33 +0000] [311] [INFO] Handling signal: term
[2018-03-01 02:24:33 +0000] [393] [INFO] Worker exiting (pid: 393)
[2018-03-01 02:24:34 +0000] [311] [INFO] Shutting down: Master
[2018-03-01 02:24:56 +0000] [308] [INFO] Starting gunicorn 19.7.1
[2018-03-01 02:24:56 +0000] [308] [INFO] Listening at: unix:carwash.sock (308)
[2018-03-01 02:24:56 +0000] [308] [INFO] Using worker: sync
[2018-03-01 02:24:56 +0000] [390] [INFO] Booting worker with pid: 390
[2018-03-01 02:24:56 +0000] [391] [INFO] Booting worker with pid: 391
[2018-03-01 02:24:56 +0000] [394] [INFO] Booting worker with pid: 394
[2018-03-02 02:25:20 +0000] [390] [INFO] Worker exiting (pid: 390)
[2018-03-02 02:25:20 +0000] [391] [INFO] Worker exiting (pid: 391)
[2018-03-02 02:25:20 +0000] [394] [INFO] Worker exiting (pid: 394)
[2018-03-02 02:25:20 +0000] [308] [INFO] Handling signal: term
[2018-03-02 02:25:21 +0000] [308] [INFO] Shutting down: Master
[2018-03-02 02:25:33 +0000] [309] [INFO] Starting gunicorn 19.7.1
[2018-03-02 02:25:33 +0000] [309] [INFO] Listening at: unix:carwash.sock (309)
[2018-03-02 02:25:33 +0000] [309] [INFO] Using worker: sync
[2018-03-02 02:25:33 +0000] [390] [INFO] Booting worker with pid: 390
[2018-03-02 02:25:33 +0000] [391] [INFO] Booting worker with pid: 391
[2018-03-02 02:25:33 +0000] [394] [INFO] Booting worker with pid: 394
[2018-03-04 09:05:48 +0000] [391] [INFO] Worker exiting (pid: 391)
[2018-03-04 09:05:48 +0000] [390] [INFO] Worker exiting (pid: 390)
[2018-03-04 09:05:48 +0000] [394] [INFO] Worker exiting (pid: 394)
[2018-03-04 09:05:48 +0000] [309] [INFO] Handling signal: term
[2018-03-04 09:05:48 +0000] [309] [INFO] Shutting down: Master
[2018-03-04 09:06:00 +0000] [312] [INFO] Starting gunicorn 19.7.1
[2018-03-04 09:06:00 +0000] [312] [INFO] Listening at: unix:carwash.sock (312)
[2018-03-04 09:06:00 +0000] [312] [INFO] Using worker: sync
[2018-03-04 09:06:00 +0000] [390] [INFO] Booting worker with pid: 390
[2018-03-04 09:06:00 +0000] [393] [INFO] Booting worker with pid: 393
[2018-03-04 09:06:00 +0000] [394] [INFO] Booting worker with pid: 394
[2018-03-05 00:56:17 +0000] [390] [ERROR] Error handling request /dashboard/edit-package/1
Traceback (most recent call last):
  File "/var/www/html/env/local/lib/python2.7/site-packages/gunicorn/workers/sync.py", line 135, in handle
    self.handle_request(listener, req, client, addr)
  File "/var/www/html/env/local/lib/python2.7/site-packages/gunicorn/workers/sync.py", line 176, in handle_request
    respiter = self.wsgi(environ, resp.start_response)
  File "/var/www/html/env/local/lib/python2.7/site-packages/flask/app.py", line 1997, in __call__
    return self.wsgi_app(environ, start_response)
  File "/var/www/html/env/local/lib/python2.7/site-packages/flask/app.py", line 1985, in wsgi_app
    response = self.handle_exception(e)
  File "/var/www/html/env/local/lib/python2.7/site-packages/flask/app.py", line 1540, in handle_exception
    reraise(exc_type, exc_value, tb)
  File "/var/www/html/env/local/lib/python2.7/site-packages/flask/app.py", line 1982, in wsgi_app
    response = self.full_dispatch_request()
  File "/var/www/html/env/local/lib/python2.7/site-packages/flask/app.py", line 1614, in full_dispatch_request
    rv = self.handle_user_exception(e)
  File "/var/www/html/env/local/lib/python2.7/site-packages/flask/app.py", line 1517, in handle_user_exception
    reraise(exc_type, exc_value, tb)
  File "/var/www/html/env/local/lib/python2.7/site-packages/flask/app.py", line 1612, in full_dispatch_request
    rv = self.dispatch_request()
  File "/var/www/html/env/local/lib/python2.7/site-packages/flask/app.py", line 1598, in dispatch_request
    return self.view_functions[rule.endpoint](**req.view_args)
  File "/var/www/html/env/local/lib/python2.7/site-packages/flask_login/utils.py", line 261, in decorated_view
    return func(*args, **kwargs)
  File "/var/www/html/c3car/app.py", line 1207, in EditPackage
    return render_template("user/edit_package.html",form=form)
  File "/var/www/html/env/local/lib/python2.7/site-packages/flask/templating.py", line 134, in render_template
    context, ctx.app)
  File "/var/www/html/env/local/lib/python2.7/site-packages/flask/templating.py", line 116, in _render
    rv = template.render(context)
  File "/var/www/html/env/local/lib/python2.7/site-packages/jinja2/environment.py", line 1008, in render
    return self.environment.handle_exception(exc_info, True)
  File "/var/www/html/env/local/lib/python2.7/site-packages/jinja2/environment.py", line 780, in handle_exception
    reraise(exc_type, exc_value, tb)
  File "/var/www/html/c3car/templates/user/edit_package.html", line 1, in top-level template code
    {% extends "layouts/dashboardtemplate.html" %}
  File "/var/www/html/c3car/templates/layouts/dashboardtemplate.html", line 324, in top-level template code
    {% block content %}
  File "/var/www/html/c3car/templates/user/edit_package.html", line 26, in block "content"
    {{ render_field(form.regular, class="form-control",placeholder="Regular")}}
  File "/var/www/html/env/local/lib/python2.7/site-packages/jinja2/runtime.py", line 579, in _invoke
    rv = self._func(*arguments)
  File "/var/www/html/c3car/templates/includes/_formhelpers.html", line 2, in template
    <dt>{{ field.label }}
  File "/var/www/html/env/local/lib/python2.7/site-packages/jinja2/environment.py", line 430, in getattr
    return getattr(obj, attribute)
UndefinedError: 'form.AddPackageForm object' has no attribute 'regular'
[2018-03-05 00:56:31 +0000] [393] [ERROR] Error handling request /dashboard/edit-package/1
Traceback (most recent call last):
  File "/var/www/html/env/local/lib/python2.7/site-packages/gunicorn/workers/sync.py", line 135, in handle
    self.handle_request(listener, req, client, addr)
  File "/var/www/html/env/local/lib/python2.7/site-packages/gunicorn/workers/sync.py", line 176, in handle_request
    respiter = self.wsgi(environ, resp.start_response)
  File "/var/www/html/env/local/lib/python2.7/site-packages/flask/app.py", line 1997, in __call__
    return self.wsgi_app(environ, start_response)
  File "/var/www/html/env/local/lib/python2.7/site-packages/flask/app.py", line 1985, in wsgi_app
    response = self.handle_exception(e)
  File "/var/www/html/env/local/lib/python2.7/site-packages/flask/app.py", line 1540, in handle_exception
    reraise(exc_type, exc_value, tb)
  File "/var/www/html/env/local/lib/python2.7/site-packages/flask/app.py", line 1982, in wsgi_app
    response = self.full_dispatch_request()
  File "/var/www/html/env/local/lib/python2.7/site-packages/flask/app.py", line 1614, in full_dispatch_request
    rv = self.handle_user_exception(e)
  File "/var/www/html/env/local/lib/python2.7/site-packages/flask/app.py", line 1517, in handle_user_exception
    reraise(exc_type, exc_value, tb)
  File "/var/www/html/env/local/lib/python2.7/site-packages/flask/app.py", line 1612, in full_dispatch_request
    rv = self.dispatch_request()
  File "/var/www/html/env/local/lib/python2.7/site-packages/flask/app.py", line 1598, in dispatch_request
    return self.view_functions[rule.endpoint](**req.view_args)
  File "/var/www/html/env/local/lib/python2.7/site-packages/flask_login/utils.py", line 261, in decorated_view
    return func(*args, **kwargs)
  File "/var/www/html/c3car/app.py", line 1207, in EditPackage
    return render_template("user/edit_package.html",form=form)
  File "/var/www/html/env/local/lib/python2.7/site-packages/flask/templating.py", line 134, in render_template
    context, ctx.app)
  File "/var/www/html/env/local/lib/python2.7/site-packages/flask/templating.py", line 116, in _render
    rv = template.render(context)
  File "/var/www/html/env/local/lib/python2.7/site-packages/jinja2/environment.py", line 1008, in render
    return self.environment.handle_exception(exc_info, True)
  File "/var/www/html/env/local/lib/python2.7/site-packages/jinja2/environment.py", line 780, in handle_exception
    reraise(exc_type, exc_value, tb)
  File "/var/www/html/c3car/templates/user/edit_package.html", line 1, in top-level template code
    {% extends "layouts/dashboardtemplate.html" %}
  File "/var/www/html/c3car/templates/layouts/dashboardtemplate.html", line 324, in top-level template code
    {% block content %}
  File "/var/www/html/c3car/templates/user/edit_package.html", line 26, in block "content"
    {{ render_field(form.regular, class="form-control",placeholder="Regular")}}
  File "/var/www/html/env/local/lib/python2.7/site-packages/jinja2/runtime.py", line 579, in _invoke
    rv = self._func(*arguments)
  File "/var/www/html/c3car/templates/includes/_formhelpers.html", line 2, in template
    <dt>{{ field.label }}
  File "/var/www/html/env/local/lib/python2.7/site-packages/jinja2/environment.py", line 430, in getattr
    return getattr(obj, attribute)
UndefinedError: 'form.AddPackageForm object' has no attribute 'regular'
[2018-03-05 01:04:49 +0000] [390] [INFO] Worker exiting (pid: 390)
[2018-03-05 01:04:49 +0000] [393] [INFO] Worker exiting (pid: 393)
[2018-03-05 01:04:49 +0000] [394] [INFO] Worker exiting (pid: 394)
[2018-03-05 01:04:49 +0000] [312] [INFO] Handling signal: term
[2018-03-05 01:04:49 +0000] [312] [INFO] Shutting down: Master
[2018-03-05 01:05:02 +0000] [307] [INFO] Starting gunicorn 19.7.1
[2018-03-05 01:05:02 +0000] [307] [INFO] Listening at: unix:carwash.sock (307)
[2018-03-05 01:05:02 +0000] [307] [INFO] Using worker: sync
[2018-03-05 01:05:02 +0000] [391] [INFO] Booting worker with pid: 391
[2018-03-05 01:05:02 +0000] [392] [INFO] Booting worker with pid: 392
[2018-03-05 01:05:02 +0000] [393] [INFO] Booting worker with pid: 393
[2018-03-05 07:50:35 +0000] [391] [INFO] Worker exiting (pid: 391)
[2018-03-05 07:50:35 +0000] [392] [INFO] Worker exiting (pid: 392)
[2018-03-05 07:50:35 +0000] [393] [INFO] Worker exiting (pid: 393)
[2018-03-05 07:50:35 +0000] [307] [INFO] Handling signal: term
[2018-03-05 07:50:35 +0000] [307] [INFO] Shutting down: Master
[2018-03-05 07:50:47 +0000] [312] [INFO] Starting gunicorn 19.7.1
[2018-03-05 07:50:47 +0000] [312] [INFO] Listening at: unix:carwash.sock (312)
[2018-03-05 07:50:47 +0000] [312] [INFO] Using worker: sync
[2018-03-05 07:50:47 +0000] [391] [INFO] Booting worker with pid: 391
[2018-03-05 07:50:48 +0000] [392] [INFO] Booting worker with pid: 392
[2018-03-05 07:50:48 +0000] [393] [INFO] Booting worker with pid: 393
[2018-03-06 01:48:18 +0000] [312] [INFO] Handling signal: term
[2018-03-06 01:48:18 +0000] [392] [INFO] Worker exiting (pid: 392)
[2018-03-06 01:48:18 +0000] [393] [INFO] Worker exiting (pid: 393)
[2018-03-06 01:48:18 +0000] [391] [INFO] Worker exiting (pid: 391)
[2018-03-06 01:48:19 +0000] [312] [INFO] Shutting down: Master
[2018-03-06 01:48:31 +0000] [311] [INFO] Starting gunicorn 19.7.1
[2018-03-06 01:48:31 +0000] [311] [INFO] Listening at: unix:carwash.sock (311)
[2018-03-06 01:48:31 +0000] [311] [INFO] Using worker: sync
[2018-03-06 01:48:31 +0000] [389] [INFO] Booting worker with pid: 389
[2018-03-06 01:48:31 +0000] [392] [INFO] Booting worker with pid: 392
[2018-03-06 01:48:31 +0000] [393] [INFO] Booting worker with pid: 393
[2018-03-06 18:27:17 +0000] [392] [ERROR] Error handling request /dashboard/invoice/9
Traceback (most recent call last):
  File "/var/www/html/env/local/lib/python2.7/site-packages/gunicorn/workers/sync.py", line 135, in handle
    self.handle_request(listener, req, client, addr)
  File "/var/www/html/env/local/lib/python2.7/site-packages/gunicorn/workers/sync.py", line 176, in handle_request
    respiter = self.wsgi(environ, resp.start_response)
  File "/var/www/html/env/local/lib/python2.7/site-packages/flask/app.py", line 1997, in __call__
    return self.wsgi_app(environ, start_response)
  File "/var/www/html/env/local/lib/python2.7/site-packages/flask/app.py", line 1985, in wsgi_app
    response = self.handle_exception(e)
  File "/var/www/html/env/local/lib/python2.7/site-packages/flask/app.py", line 1540, in handle_exception
    reraise(exc_type, exc_value, tb)
  File "/var/www/html/env/local/lib/python2.7/site-packages/flask/app.py", line 1982, in wsgi_app
    response = self.full_dispatch_request()
  File "/var/www/html/env/local/lib/python2.7/site-packages/flask/app.py", line 1614, in full_dispatch_request
    rv = self.handle_user_exception(e)
  File "/var/www/html/env/local/lib/python2.7/site-packages/flask/app.py", line 1517, in handle_user_exception
    reraise(exc_type, exc_value, tb)
  File "/var/www/html/env/local/lib/python2.7/site-packages/flask/app.py", line 1612, in full_dispatch_request
    rv = self.dispatch_request()
  File "/var/www/html/env/local/lib/python2.7/site-packages/flask/app.py", line 1598, in dispatch_request
    return self.view_functions[rule.endpoint](**req.view_args)
  File "/var/www/html/env/local/lib/python2.7/site-packages/flask_login/utils.py", line 261, in decorated_view
    return func(*args, **kwargs)
  File "/var/www/html/c3car/app.py", line 1496, in UserInvoice
    user = User.query.filter_by(id=invoice.owner).first()
AttributeError: 'NoneType' object has no attribute 'owner'
[2018-03-07 08:20:06 +0000] [393] [INFO] Worker exiting (pid: 393)
[2018-03-07 08:20:06 +0000] [392] [INFO] Worker exiting (pid: 392)
[2018-03-07 08:20:06 +0000] [389] [INFO] Worker exiting (pid: 389)
[2018-03-07 08:20:06 +0000] [311] [INFO] Handling signal: term
[2018-03-07 08:20:06 +0000] [311] [INFO] Shutting down: Master
[2018-03-07 08:20:29 +0000] [312] [INFO] Starting gunicorn 19.7.1
[2018-03-07 08:20:29 +0000] [312] [INFO] Listening at: unix:carwash.sock (312)
[2018-03-07 08:20:29 +0000] [312] [INFO] Using worker: sync
[2018-03-07 08:20:29 +0000] [390] [INFO] Booting worker with pid: 390
[2018-03-07 08:20:29 +0000] [391] [INFO] Booting worker with pid: 391
[2018-03-07 08:20:29 +0000] [394] [INFO] Booting worker with pid: 394
[2018-03-07 08:57:49 +0000] [390] [INFO] Worker exiting (pid: 390)
[2018-03-07 08:57:49 +0000] [391] [INFO] Worker exiting (pid: 391)
[2018-03-07 08:57:49 +0000] [394] [INFO] Worker exiting (pid: 394)
[2018-03-07 08:57:49 +0000] [312] [INFO] Handling signal: term
[2018-03-07 08:57:50 +0000] [312] [INFO] Shutting down: Master
[2018-03-07 08:58:02 +0000] [313] [INFO] Starting gunicorn 19.7.1
[2018-03-07 08:58:02 +0000] [313] [INFO] Listening at: unix:carwash.sock (313)
[2018-03-07 08:58:02 +0000] [313] [INFO] Using worker: sync
[2018-03-07 08:58:02 +0000] [393] [INFO] Booting worker with pid: 393
[2018-03-07 08:58:02 +0000] [394] [INFO] Booting worker with pid: 394
[2018-03-07 08:58:02 +0000] [395] [INFO] Booting worker with pid: 395
[2018-03-07 23:13:20 +0000] [394] [INFO] Worker exiting (pid: 394)
[2018-03-07 23:13:20 +0000] [393] [INFO] Worker exiting (pid: 393)
[2018-03-07 23:13:20 +0000] [395] [INFO] Worker exiting (pid: 395)
[2018-03-07 23:13:20 +0000] [313] [INFO] Handling signal: term
[2018-03-07 23:13:20 +0000] [313] [INFO] Shutting down: Master
[2018-03-07 23:13:42 +0000] [313] [INFO] Starting gunicorn 19.7.1
[2018-03-07 23:13:42 +0000] [313] [INFO] Listening at: unix:carwash.sock (313)
[2018-03-07 23:13:42 +0000] [313] [INFO] Using worker: sync
[2018-03-07 23:13:42 +0000] [391] [INFO] Booting worker with pid: 391
[2018-03-07 23:13:42 +0000] [392] [INFO] Booting worker with pid: 392
[2018-03-07 23:13:42 +0000] [393] [INFO] Booting worker with pid: 393
[2018-03-08 11:21:06 +0000] [393] [ERROR] Error handling request /dashboard/invoice/11
Traceback (most recent call last):
  File "/var/www/html/env/local/lib/python2.7/site-packages/gunicorn/workers/sync.py", line 135, in handle
    self.handle_request(listener, req, client, addr)
  File "/var/www/html/env/local/lib/python2.7/site-packages/gunicorn/workers/sync.py", line 176, in handle_request
    respiter = self.wsgi(environ, resp.start_response)
  File "/var/www/html/env/local/lib/python2.7/site-packages/flask/app.py", line 1997, in __call__
    return self.wsgi_app(environ, start_response)
  File "/var/www/html/env/local/lib/python2.7/site-packages/flask/app.py", line 1985, in wsgi_app
    response = self.handle_exception(e)
  File "/var/www/html/env/local/lib/python2.7/site-packages/flask/app.py", line 1540, in handle_exception
    reraise(exc_type, exc_value, tb)
  File "/var/www/html/env/local/lib/python2.7/site-packages/flask/app.py", line 1982, in wsgi_app
    response = self.full_dispatch_request()
  File "/var/www/html/env/local/lib/python2.7/site-packages/flask/app.py", line 1615, in full_dispatch_request
    return self.finalize_request(rv)
  File "/var/www/html/env/local/lib/python2.7/site-packages/flask/app.py", line 1630, in finalize_request
    response = self.make_response(rv)
  File "/var/www/html/env/local/lib/python2.7/site-packages/flask/app.py", line 1725, in make_response
    raise ValueError('View function did not return a response')
ValueError: View function did not return a response
[2018-03-08 11:21:24 +0000] [393] [ERROR] Error handling request /dashboard/invoice/10
Traceback (most recent call last):
  File "/var/www/html/env/local/lib/python2.7/site-packages/gunicorn/workers/sync.py", line 135, in handle
    self.handle_request(listener, req, client, addr)
  File "/var/www/html/env/local/lib/python2.7/site-packages/gunicorn/workers/sync.py", line 176, in handle_request
    respiter = self.wsgi(environ, resp.start_response)
  File "/var/www/html/env/local/lib/python2.7/site-packages/flask/app.py", line 1997, in __call__
    return self.wsgi_app(environ, start_response)
  File "/var/www/html/env/local/lib/python2.7/site-packages/flask/app.py", line 1985, in wsgi_app
    response = self.handle_exception(e)
  File "/var/www/html/env/local/lib/python2.7/site-packages/flask/app.py", line 1540, in handle_exception
    reraise(exc_type, exc_value, tb)
  File "/var/www/html/env/local/lib/python2.7/site-packages/flask/app.py", line 1982, in wsgi_app
    response = self.full_dispatch_request()
  File "/var/www/html/env/local/lib/python2.7/site-packages/flask/app.py", line 1615, in full_dispatch_request
    return self.finalize_request(rv)
  File "/var/www/html/env/local/lib/python2.7/site-packages/flask/app.py", line 1630, in finalize_request
    response = self.make_response(rv)
  File "/var/www/html/env/local/lib/python2.7/site-packages/flask/app.py", line 1725, in make_response
    raise ValueError('View function did not return a response')
ValueError: View function did not return a response
[2018-03-08 11:31:57 +0000] [391] [ERROR] Error handling request /dashboard/invoice/11
Traceback (most recent call last):
  File "/var/www/html/env/local/lib/python2.7/site-packages/gunicorn/workers/sync.py", line 135, in handle
    self.handle_request(listener, req, client, addr)
  File "/var/www/html/env/local/lib/python2.7/site-packages/gunicorn/workers/sync.py", line 176, in handle_request
    respiter = self.wsgi(environ, resp.start_response)
  File "/var/www/html/env/local/lib/python2.7/site-packages/flask/app.py", line 1997, in __call__
    return self.wsgi_app(environ, start_response)
  File "/var/www/html/env/local/lib/python2.7/site-packages/flask/app.py", line 1985, in wsgi_app
    response = self.handle_exception(e)
  File "/var/www/html/env/local/lib/python2.7/site-packages/flask/app.py", line 1540, in handle_exception
    reraise(exc_type, exc_value, tb)
  File "/var/www/html/env/local/lib/python2.7/site-packages/flask/app.py", line 1982, in wsgi_app
    response = self.full_dispatch_request()
  File "/var/www/html/env/local/lib/python2.7/site-packages/flask/app.py", line 1615, in full_dispatch_request
    return self.finalize_request(rv)
  File "/var/www/html/env/local/lib/python2.7/site-packages/flask/app.py", line 1630, in finalize_request
    response = self.make_response(rv)
  File "/var/www/html/env/local/lib/python2.7/site-packages/flask/app.py", line 1725, in make_response
    raise ValueError('View function did not return a response')
ValueError: View function did not return a response
[2018-03-09 00:06:56 +0000] [391] [INFO] Worker exiting (pid: 391)
[2018-03-09 00:06:56 +0000] [392] [INFO] Worker exiting (pid: 392)
[2018-03-09 00:06:56 +0000] [393] [INFO] Worker exiting (pid: 393)
[2018-03-09 00:06:56 +0000] [313] [INFO] Handling signal: term
[2018-03-09 00:06:56 +0000] [313] [INFO] Shutting down: Master
[2018-03-09 00:07:18 +0000] [309] [INFO] Starting gunicorn 19.7.1
[2018-03-09 00:07:18 +0000] [309] [INFO] Listening at: unix:carwash.sock (309)
[2018-03-09 00:07:18 +0000] [309] [INFO] Using worker: sync
[2018-03-09 00:07:18 +0000] [391] [INFO] Booting worker with pid: 391
[2018-03-09 00:07:18 +0000] [392] [INFO] Booting worker with pid: 392
[2018-03-09 00:07:18 +0000] [393] [INFO] Booting worker with pid: 393
[2018-03-09 00:11:20 +0000] [391] [ERROR] Error handling request /dashboard/location/transaction/1
Traceback (most recent call last):
  File "/var/www/html/env/local/lib/python2.7/site-packages/gunicorn/workers/sync.py", line 135, in handle
    self.handle_request(listener, req, client, addr)
  File "/var/www/html/env/local/lib/python2.7/site-packages/gunicorn/workers/sync.py", line 176, in handle_request
    respiter = self.wsgi(environ, resp.start_response)
  File "/var/www/html/env/local/lib/python2.7/site-packages/flask/app.py", line 1997, in __call__
    return self.wsgi_app(environ, start_response)
  File "/var/www/html/env/local/lib/python2.7/site-packages/flask/app.py", line 1985, in wsgi_app
    response = self.handle_exception(e)
  File "/var/www/html/env/local/lib/python2.7/site-packages/flask/app.py", line 1540, in handle_exception
    reraise(exc_type, exc_value, tb)
  File "/var/www/html/env/local/lib/python2.7/site-packages/flask/app.py", line 1982, in wsgi_app
    response = self.full_dispatch_request()
  File "/var/www/html/env/local/lib/python2.7/site-packages/flask/app.py", line 1614, in full_dispatch_request
    rv = self.handle_user_exception(e)
  File "/var/www/html/env/local/lib/python2.7/site-packages/flask/app.py", line 1517, in handle_user_exception
    reraise(exc_type, exc_value, tb)
  File "/var/www/html/env/local/lib/python2.7/site-packages/flask/app.py", line 1612, in full_dispatch_request
    rv = self.dispatch_request()
  File "/var/www/html/env/local/lib/python2.7/site-packages/flask/app.py", line 1598, in dispatch_request
    return self.view_functions[rule.endpoint](**req.view_args)
  File "/var/www/html/env/local/lib/python2.7/site-packages/flask_login/utils.py", line 261, in decorated_view
    return func(*args, **kwargs)
  File "/var/www/html/c3car/app.py", line 1392, in Transaction
    transactions = Accounting.query.filter_by(location=name).all()
  File "/var/www/html/env/local/lib/python2.7/site-packages/sqlalchemy/orm/query.py", line 2726, in all
    return list(self)
  File "/var/www/html/env/local/lib/python2.7/site-packages/sqlalchemy/orm/query.py", line 2878, in __iter__
    return self._execute_and_instances(context)
  File "/var/www/html/env/local/lib/python2.7/site-packages/sqlalchemy/orm/query.py", line 2901, in _execute_and_instances
    result = conn.execute(querycontext.statement, self._params)
  File "/var/www/html/env/local/lib/python2.7/site-packages/sqlalchemy/engine/base.py", line 948, in execute
    return meth(self, multiparams, params)
  File "/var/www/html/env/local/lib/python2.7/site-packages/sqlalchemy/sql/elements.py", line 269, in _execute_on_connection
    return connection._execute_clauseelement(self, multiparams, params)
  File "/var/www/html/env/local/lib/python2.7/site-packages/sqlalchemy/engine/base.py", line 1060, in _execute_clauseelement
    compiled_sql, distilled_params
  File "/var/www/html/env/local/lib/python2.7/site-packages/sqlalchemy/engine/base.py", line 1200, in _execute_context
    context)
  File "/var/www/html/env/local/lib/python2.7/site-packages/sqlalchemy/engine/base.py", line 1413, in _handle_dbapi_exception
    exc_info
  File "/var/www/html/env/local/lib/python2.7/site-packages/sqlalchemy/util/compat.py", line 203, in raise_from_cause
    reraise(type(exception), exception, tb=exc_tb, cause=cause)
  File "/var/www/html/env/local/lib/python2.7/site-packages/sqlalchemy/engine/base.py", line 1193, in _execute_context
    context)
  File "/var/www/html/env/local/lib/python2.7/site-packages/sqlalchemy/engine/default.py", line 507, in do_execute
    cursor.execute(statement, parameters)
  File "/var/www/html/env/local/lib/python2.7/site-packages/MySQLdb/cursors.py", line 205, in execute
    self.errorhandler(self, exc, value)
  File "/var/www/html/env/local/lib/python2.7/site-packages/MySQLdb/connections.py", line 36, in defaulterrorhandler
    raise errorclass, errorvalue
ProgrammingError: (_mysql_exceptions.ProgrammingError) (1146, "Table 'c3carwash.accounting' doesn't exist") [SQL: u'SELECT accounting.id AS accounting_id, accounting.description AS accounting_description, accounting.location AS accounting_location, accounting.amount AS accounting_amount, accounting.status AS accounting_status, accounting.date AS accounting_date, accounting.cashier AS accounting_cashier, accounting.pakets AS accounting_pakets, accounting.customer AS accounting_customer, accounting.member AS accounting_member \nFROM accounting \nWHERE accounting.location = %s'] [parameters: ('Batubulan',)] (Background on this error at: http://sqlalche.me/e/f405)
[2018-03-09 00:11:37 +0000] [391] [INFO] Worker exiting (pid: 391)
[2018-03-09 00:11:37 +0000] [392] [INFO] Worker exiting (pid: 392)
[2018-03-09 00:11:37 +0000] [393] [INFO] Worker exiting (pid: 393)
[2018-03-09 00:11:37 +0000] [309] [INFO] Handling signal: term
[2018-03-09 00:11:37 +0000] [309] [INFO] Shutting down: Master
[2018-03-09 00:11:50 +0000] [310] [INFO] Starting gunicorn 19.7.1
[2018-03-09 00:11:50 +0000] [310] [INFO] Listening at: unix:carwash.sock (310)
[2018-03-09 00:11:50 +0000] [310] [INFO] Using worker: sync
[2018-03-09 00:11:50 +0000] [391] [INFO] Booting worker with pid: 391
[2018-03-09 00:11:50 +0000] [394] [INFO] Booting worker with pid: 394
[2018-03-09 00:11:50 +0000] [395] [INFO] Booting worker with pid: 395
[2018-03-09 01:18:48 +0000] [391] [ERROR] Error handling request /dashboard/location/transaction/1
Traceback (most recent call last):
  File "/var/www/html/env/local/lib/python2.7/site-packages/gunicorn/workers/sync.py", line 135, in handle
    self.handle_request(listener, req, client, addr)
  File "/var/www/html/env/local/lib/python2.7/site-packages/gunicorn/workers/sync.py", line 176, in handle_request
    respiter = self.wsgi(environ, resp.start_response)
  File "/var/www/html/env/local/lib/python2.7/site-packages/flask/app.py", line 1997, in __call__
    return self.wsgi_app(environ, start_response)
  File "/var/www/html/env/local/lib/python2.7/site-packages/flask/app.py", line 1985, in wsgi_app
    response = self.handle_exception(e)
  File "/var/www/html/env/local/lib/python2.7/site-packages/flask/app.py", line 1540, in handle_exception
    reraise(exc_type, exc_value, tb)
  File "/var/www/html/env/local/lib/python2.7/site-packages/flask/app.py", line 1982, in wsgi_app
    response = self.full_dispatch_request()
  File "/var/www/html/env/local/lib/python2.7/site-packages/flask/app.py", line 1614, in full_dispatch_request
    rv = self.handle_user_exception(e)
  File "/var/www/html/env/local/lib/python2.7/site-packages/flask/app.py", line 1517, in handle_user_exception
    reraise(exc_type, exc_value, tb)
  File "/var/www/html/env/local/lib/python2.7/site-packages/flask/app.py", line 1612, in full_dispatch_request
    rv = self.dispatch_request()
  File "/var/www/html/env/local/lib/python2.7/site-packages/flask/app.py", line 1598, in dispatch_request
    return self.view_functions[rule.endpoint](**req.view_args)
  File "/var/www/html/env/local/lib/python2.7/site-packages/flask_login/utils.py", line 261, in decorated_view
    return func(*args, **kwargs)
  File "/var/www/html/c3car/app.py", line 1398, in Transaction
    return render_template("user/all_transaction.html",transactions=transactions,form=form,name=name,location=location)
  File "/var/www/html/env/local/lib/python2.7/site-packages/flask/templating.py", line 134, in render_template
    context, ctx.app)
  File "/var/www/html/env/local/lib/python2.7/site-packages/flask/templating.py", line 116, in _render
    rv = template.render(context)
  File "/var/www/html/env/local/lib/python2.7/site-packages/jinja2/environment.py", line 1008, in render
    return self.environment.handle_exception(exc_info, True)
  File "/var/www/html/env/local/lib/python2.7/site-packages/jinja2/environment.py", line 780, in handle_exception
    reraise(exc_type, exc_value, tb)
  File "/var/www/html/c3car/templates/user/all_transaction.html", line 1, in top-level template code
    {% extends "layouts/dashboardtemplate.html" %}
  File "/var/www/html/c3car/templates/layouts/dashboardtemplate.html", line 333, in top-level template code
    {% block content %}
  File "/var/www/html/c3car/templates/user/all_transaction.html", line 73, in block "content"
    <td>{{ ",".join(trans.pakets) }}</td>
TypeError: can only join an iterable
[2018-03-09 01:18:59 +0000] [394] [ERROR] Error handling request /dashboard/location/transaction/1
Traceback (most recent call last):
  File "/var/www/html/env/local/lib/python2.7/site-packages/gunicorn/workers/sync.py", line 135, in handle
    self.handle_request(listener, req, client, addr)
  File "/var/www/html/env/local/lib/python2.7/site-packages/gunicorn/workers/sync.py", line 176, in handle_request
    respiter = self.wsgi(environ, resp.start_response)
  File "/var/www/html/env/local/lib/python2.7/site-packages/flask/app.py", line 1997, in __call__
    return self.wsgi_app(environ, start_response)
  File "/var/www/html/env/local/lib/python2.7/site-packages/flask/app.py", line 1985, in wsgi_app
    response = self.handle_exception(e)
  File "/var/www/html/env/local/lib/python2.7/site-packages/flask/app.py", line 1540, in handle_exception
    reraise(exc_type, exc_value, tb)
  File "/var/www/html/env/local/lib/python2.7/site-packages/flask/app.py", line 1982, in wsgi_app
    response = self.full_dispatch_request()
  File "/var/www/html/env/local/lib/python2.7/site-packages/flask/app.py", line 1614, in full_dispatch_request
    rv = self.handle_user_exception(e)
  File "/var/www/html/env/local/lib/python2.7/site-packages/flask/app.py", line 1517, in handle_user_exception
    reraise(exc_type, exc_value, tb)
  File "/var/www/html/env/local/lib/python2.7/site-packages/flask/app.py", line 1612, in full_dispatch_request
    rv = self.dispatch_request()
  File "/var/www/html/env/local/lib/python2.7/site-packages/flask/app.py", line 1598, in dispatch_request
    return self.view_functions[rule.endpoint](**req.view_args)
  File "/var/www/html/env/local/lib/python2.7/site-packages/flask_login/utils.py", line 261, in decorated_view
    return func(*args, **kwargs)
  File "/var/www/html/c3car/app.py", line 1398, in Transaction
    return render_template("user/all_transaction.html",transactions=transactions,form=form,name=name,location=location)
  File "/var/www/html/env/local/lib/python2.7/site-packages/flask/templating.py", line 134, in render_template
    context, ctx.app)
  File "/var/www/html/env/local/lib/python2.7/site-packages/flask/templating.py", line 116, in _render
    rv = template.render(context)
  File "/var/www/html/env/local/lib/python2.7/site-packages/jinja2/environment.py", line 1008, in render
    return self.environment.handle_exception(exc_info, True)
  File "/var/www/html/env/local/lib/python2.7/site-packages/jinja2/environment.py", line 780, in handle_exception
    reraise(exc_type, exc_value, tb)
  File "/var/www/html/c3car/templates/user/all_transaction.html", line 1, in top-level template code
    {% extends "layouts/dashboardtemplate.html" %}
  File "/var/www/html/c3car/templates/layouts/dashboardtemplate.html", line 333, in top-level template code
    {% block content %}
  File "/var/www/html/c3car/templates/user/all_transaction.html", line 73, in block "content"
    <td>{{ ",".join(trans.pakets) }}</td>
TypeError: can only join an iterable
[2018-03-09 01:19:01 +0000] [395] [ERROR] Error handling request /dashboard/location/transaction/1
Traceback (most recent call last):
  File "/var/www/html/env/local/lib/python2.7/site-packages/gunicorn/workers/sync.py", line 135, in handle
    self.handle_request(listener, req, client, addr)
  File "/var/www/html/env/local/lib/python2.7/site-packages/gunicorn/workers/sync.py", line 176, in handle_request
    respiter = self.wsgi(environ, resp.start_response)
  File "/var/www/html/env/local/lib/python2.7/site-packages/flask/app.py", line 1997, in __call__
    return self.wsgi_app(environ, start_response)
  File "/var/www/html/env/local/lib/python2.7/site-packages/flask/app.py", line 1985, in wsgi_app
    response = self.handle_exception(e)
  File "/var/www/html/env/local/lib/python2.7/site-packages/flask/app.py", line 1540, in handle_exception
    reraise(exc_type, exc_value, tb)
  File "/var/www/html/env/local/lib/python2.7/site-packages/flask/app.py", line 1982, in wsgi_app
    response = self.full_dispatch_request()
  File "/var/www/html/env/local/lib/python2.7/site-packages/flask/app.py", line 1614, in full_dispatch_request
    rv = self.handle_user_exception(e)
  File "/var/www/html/env/local/lib/python2.7/site-packages/flask/app.py", line 1517, in handle_user_exception
    reraise(exc_type, exc_value, tb)
  File "/var/www/html/env/local/lib/python2.7/site-packages/flask/app.py", line 1612, in full_dispatch_request
    rv = self.dispatch_request()
  File "/var/www/html/env/local/lib/python2.7/site-packages/flask/app.py", line 1598, in dispatch_request
    return self.view_functions[rule.endpoint](**req.view_args)
  File "/var/www/html/env/local/lib/python2.7/site-packages/flask_login/utils.py", line 261, in decorated_view
    return func(*args, **kwargs)
  File "/var/www/html/c3car/app.py", line 1398, in Transaction
    return render_template("user/all_transaction.html",transactions=transactions,form=form,name=name,location=location)
  File "/var/www/html/env/local/lib/python2.7/site-packages/flask/templating.py", line 134, in render_template
    context, ctx.app)
  File "/var/www/html/env/local/lib/python2.7/site-packages/flask/templating.py", line 116, in _render
    rv = template.render(context)
  File "/var/www/html/env/local/lib/python2.7/site-packages/jinja2/environment.py", line 1008, in render
    return self.environment.handle_exception(exc_info, True)
  File "/var/www/html/env/local/lib/python2.7/site-packages/jinja2/environment.py", line 780, in handle_exception
    reraise(exc_type, exc_value, tb)
  File "/var/www/html/c3car/templates/user/all_transaction.html", line 1, in top-level template code
    {% extends "layouts/dashboardtemplate.html" %}
  File "/var/www/html/c3car/templates/layouts/dashboardtemplate.html", line 333, in top-level template code
    {% block content %}
  File "/var/www/html/c3car/templates/user/all_transaction.html", line 73, in block "content"
    <td>{{ ",".join(trans.pakets) }}</td>
TypeError: can only join an iterable
[2018-03-09 01:40:28 +0000] [394] [ERROR] Error handling request /dashboard/location/transaction/1
Traceback (most recent call last):
  File "/var/www/html/env/local/lib/python2.7/site-packages/gunicorn/workers/sync.py", line 135, in handle
    self.handle_request(listener, req, client, addr)
  File "/var/www/html/env/local/lib/python2.7/site-packages/gunicorn/workers/sync.py", line 176, in handle_request
    respiter = self.wsgi(environ, resp.start_response)
  File "/var/www/html/env/local/lib/python2.7/site-packages/flask/app.py", line 1997, in __call__
    return self.wsgi_app(environ, start_response)
  File "/var/www/html/env/local/lib/python2.7/site-packages/flask/app.py", line 1985, in wsgi_app
    response = self.handle_exception(e)
  File "/var/www/html/env/local/lib/python2.7/site-packages/flask/app.py", line 1540, in handle_exception
    reraise(exc_type, exc_value, tb)
  File "/var/www/html/env/local/lib/python2.7/site-packages/flask/app.py", line 1982, in wsgi_app
    response = self.full_dispatch_request()
  File "/var/www/html/env/local/lib/python2.7/site-packages/flask/app.py", line 1614, in full_dispatch_request
    rv = self.handle_user_exception(e)
  File "/var/www/html/env/local/lib/python2.7/site-packages/flask/app.py", line 1517, in handle_user_exception
    reraise(exc_type, exc_value, tb)
  File "/var/www/html/env/local/lib/python2.7/site-packages/flask/app.py", line 1612, in full_dispatch_request
    rv = self.dispatch_request()
  File "/var/www/html/env/local/lib/python2.7/site-packages/flask/app.py", line 1598, in dispatch_request
    return self.view_functions[rule.endpoint](**req.view_args)
  File "/var/www/html/env/local/lib/python2.7/site-packages/flask_login/utils.py", line 261, in decorated_view
    return func(*args, **kwargs)
  File "/var/www/html/c3car/app.py", line 1398, in Transaction
    return render_template("user/all_transaction.html",transactions=transactions,form=form,name=name,location=location)
  File "/var/www/html/env/local/lib/python2.7/site-packages/flask/templating.py", line 134, in render_template
    context, ctx.app)
  File "/var/www/html/env/local/lib/python2.7/site-packages/flask/templating.py", line 116, in _render
    rv = template.render(context)
  File "/var/www/html/env/local/lib/python2.7/site-packages/jinja2/environment.py", line 1008, in render
    return self.environment.handle_exception(exc_info, True)
  File "/var/www/html/env/local/lib/python2.7/site-packages/jinja2/environment.py", line 780, in handle_exception
    reraise(exc_type, exc_value, tb)
  File "/var/www/html/c3car/templates/user/all_transaction.html", line 1, in top-level template code
    {% extends "layouts/dashboardtemplate.html" %}
  File "/var/www/html/c3car/templates/layouts/dashboardtemplate.html", line 333, in top-level template code
    {% block content %}
  File "/var/www/html/c3car/templates/user/all_transaction.html", line 73, in block "content"
    <td>{{ ",".join(trans.pakets) }}</td>
TypeError: can only join an iterable
[2018-03-09 01:55:23 +0000] [394] [INFO] Worker exiting (pid: 394)
[2018-03-09 01:55:23 +0000] [395] [INFO] Worker exiting (pid: 395)
[2018-03-09 01:55:23 +0000] [391] [INFO] Worker exiting (pid: 391)
[2018-03-09 01:55:23 +0000] [310] [INFO] Handling signal: term
[2018-03-09 01:55:23 +0000] [310] [INFO] Shutting down: Master
[2018-03-09 01:55:36 +0000] [310] [INFO] Starting gunicorn 19.7.1
[2018-03-09 01:55:36 +0000] [310] [INFO] Listening at: unix:carwash.sock (310)
[2018-03-09 01:55:36 +0000] [310] [INFO] Using worker: sync
[2018-03-09 01:55:36 +0000] [392] [INFO] Booting worker with pid: 392
[2018-03-09 01:55:36 +0000] [393] [INFO] Booting worker with pid: 393
[2018-03-09 01:55:36 +0000] [394] [INFO] Booting worker with pid: 394
[2018-03-09 22:45:02 +0000] [393] [ERROR] Error handling request /dashboard/cancel-antrean/17
Traceback (most recent call last):
  File "/var/www/html/env/local/lib/python2.7/site-packages/gunicorn/workers/sync.py", line 135, in handle
    self.handle_request(listener, req, client, addr)
  File "/var/www/html/env/local/lib/python2.7/site-packages/gunicorn/workers/sync.py", line 176, in handle_request
    respiter = self.wsgi(environ, resp.start_response)
  File "/var/www/html/env/local/lib/python2.7/site-packages/flask/app.py", line 1997, in __call__
    return self.wsgi_app(environ, start_response)
  File "/var/www/html/env/local/lib/python2.7/site-packages/flask/app.py", line 1985, in wsgi_app
    response = self.handle_exception(e)
  File "/var/www/html/env/local/lib/python2.7/site-packages/flask/app.py", line 1540, in handle_exception
    reraise(exc_type, exc_value, tb)
  File "/var/www/html/env/local/lib/python2.7/site-packages/flask/app.py", line 1982, in wsgi_app
    response = self.full_dispatch_request()
  File "/var/www/html/env/local/lib/python2.7/site-packages/flask/app.py", line 1614, in full_dispatch_request
    rv = self.handle_user_exception(e)
  File "/var/www/html/env/local/lib/python2.7/site-packages/flask/app.py", line 1517, in handle_user_exception
    reraise(exc_type, exc_value, tb)
  File "/var/www/html/env/local/lib/python2.7/site-packages/flask/app.py", line 1612, in full_dispatch_request
    rv = self.dispatch_request()
  File "/var/www/html/env/local/lib/python2.7/site-packages/flask/app.py", line 1598, in dispatch_request
    return self.view_functions[rule.endpoint](**req.view_args)
  File "/var/www/html/env/local/lib/python2.7/site-packages/flask_login/utils.py", line 261, in decorated_view
    return func(*args, **kwargs)
  File "/var/www/html/c3car/app.py", line 1060, in CancelAntrean
    location = Location.query.filter_by(location=book.location).first()
AttributeError: 'NoneType' object has no attribute 'location'
[2018-03-10 12:22:05 +0000] [392] [INFO] Worker exiting (pid: 392)
[2018-03-10 12:22:05 +0000] [393] [INFO] Worker exiting (pid: 393)
[2018-03-10 12:22:05 +0000] [394] [INFO] Worker exiting (pid: 394)
[2018-03-10 12:22:06 +0000] [310] [INFO] Handling signal: term
[2018-03-10 12:22:06 +0000] [310] [INFO] Shutting down: Master
[2018-03-10 12:22:28 +0000] [309] [INFO] Starting gunicorn 19.7.1
[2018-03-10 12:22:28 +0000] [309] [INFO] Listening at: unix:carwash.sock (309)
[2018-03-10 12:22:28 +0000] [309] [INFO] Using worker: sync
[2018-03-10 12:22:28 +0000] [390] [INFO] Booting worker with pid: 390
[2018-03-10 12:22:28 +0000] [391] [INFO] Booting worker with pid: 391
[2018-03-10 12:22:28 +0000] [392] [INFO] Booting worker with pid: 392
[2018-03-10 12:23:44 +0000] [391] [ERROR] Error handling request /dashboard/admin/delete-invoice/16
Traceback (most recent call last):
  File "/var/www/html/env/local/lib/python2.7/site-packages/gunicorn/workers/sync.py", line 135, in handle
    self.handle_request(listener, req, client, addr)
  File "/var/www/html/env/local/lib/python2.7/site-packages/gunicorn/workers/sync.py", line 176, in handle_request
    respiter = self.wsgi(environ, resp.start_response)
  File "/var/www/html/env/local/lib/python2.7/site-packages/flask/app.py", line 1997, in __call__
    return self.wsgi_app(environ, start_response)
  File "/var/www/html/env/local/lib/python2.7/site-packages/flask/app.py", line 1985, in wsgi_app
    response = self.handle_exception(e)
  File "/var/www/html/env/local/lib/python2.7/site-packages/flask/app.py", line 1540, in handle_exception
    reraise(exc_type, exc_value, tb)
  File "/var/www/html/env/local/lib/python2.7/site-packages/flask/app.py", line 1982, in wsgi_app
    response = self.full_dispatch_request()
  File "/var/www/html/env/local/lib/python2.7/site-packages/flask/app.py", line 1614, in full_dispatch_request
    rv = self.handle_user_exception(e)
  File "/var/www/html/env/local/lib/python2.7/site-packages/flask/app.py", line 1517, in handle_user_exception
    reraise(exc_type, exc_value, tb)
  File "/var/www/html/env/local/lib/python2.7/site-packages/flask/app.py", line 1612, in full_dispatch_request
    rv = self.dispatch_request()
  File "/var/www/html/env/local/lib/python2.7/site-packages/flask/app.py", line 1598, in dispatch_request
    return self.view_functions[rule.endpoint](**req.view_args)
  File "/var/www/html/env/local/lib/python2.7/site-packages/flask_login/utils.py", line 261, in decorated_view
    return func(*args, **kwargs)
  File "/var/www/html/c3car/app.py", line 1252, in DeleteInvoiceByYudi
    db.session.delete(book)
  File "/var/www/html/env/local/lib/python2.7/site-packages/sqlalchemy/orm/scoping.py", line 153, in do
    return getattr(self.registry(), name)(*args, **kwargs)
  File "/var/www/html/env/local/lib/python2.7/site-packages/sqlalchemy/orm/session.py", line 1810, in delete
    raise exc.UnmappedInstanceError(instance)
UnmappedInstanceError: Class '__builtin__.NoneType' is not mapped
[2018-03-10 13:07:15 +0000] [391] [INFO] Worker exiting (pid: 391)
[2018-03-10 13:07:15 +0000] [309] [INFO] Handling signal: term
[2018-03-10 13:07:15 +0000] [390] [INFO] Worker exiting (pid: 390)
[2018-03-10 13:07:15 +0000] [392] [INFO] Worker exiting (pid: 392)
[2018-03-10 13:07:16 +0000] [309] [INFO] Shutting down: Master
[2018-03-10 13:07:28 +0000] [310] [INFO] Starting gunicorn 19.7.1
[2018-03-10 13:07:28 +0000] [310] [INFO] Listening at: unix:carwash.sock (310)
[2018-03-10 13:07:28 +0000] [310] [INFO] Using worker: sync
[2018-03-10 13:07:28 +0000] [389] [INFO] Booting worker with pid: 389
[2018-03-10 13:07:28 +0000] [390] [INFO] Booting worker with pid: 390
[2018-03-10 13:07:28 +0000] [391] [INFO] Booting worker with pid: 391
[2018-03-10 13:07:31 +0000] [389] [ERROR] Exception in worker process
Traceback (most recent call last):
  File "/var/www/html/env/local/lib/python2.7/site-packages/gunicorn/arbiter.py", line 578, in spawn_worker
    worker.init_process()
  File "/var/www/html/env/local/lib/python2.7/site-packages/gunicorn/workers/base.py", line 126, in init_process
    self.load_wsgi()
  File "/var/www/html/env/local/lib/python2.7/site-packages/gunicorn/workers/base.py", line 135, in load_wsgi
    self.wsgi = self.app.wsgi()
  File "/var/www/html/env/local/lib/python2.7/site-packages/gunicorn/app/base.py", line 67, in wsgi
    self.callable = self.load()
  File "/var/www/html/env/local/lib/python2.7/site-packages/gunicorn/app/wsgiapp.py", line 65, in load
    return self.load_wsgiapp()
  File "/var/www/html/env/local/lib/python2.7/site-packages/gunicorn/app/wsgiapp.py", line 52, in load_wsgiapp
    return util.import_app(self.app_uri)
  File "/var/www/html/env/local/lib/python2.7/site-packages/gunicorn/util.py", line 352, in import_app
    __import__(module)
  File "/var/www/html/c3car/wsgi.py", line 1, in <module>
    from app import app
  File "/var/www/html/c3car/app.py", line 7, in <module>
    from pytz import timezone
ImportError: No module named pytz
[2018-03-10 13:07:31 +0000] [390] [ERROR] Exception in worker process
Traceback (most recent call last):
  File "/var/www/html/env/local/lib/python2.7/site-packages/gunicorn/arbiter.py", line 578, in spawn_worker
    worker.init_process()
  File "/var/www/html/env/local/lib/python2.7/site-packages/gunicorn/workers/base.py", line 126, in init_process
    self.load_wsgi()
  File "/var/www/html/env/local/lib/python2.7/site-packages/gunicorn/workers/base.py", line 135, in load_wsgi
    self.wsgi = self.app.wsgi()
  File "/var/www/html/env/local/lib/python2.7/site-packages/gunicorn/app/base.py", line 67, in wsgi
    self.callable = self.load()
  File "/var/www/html/env/local/lib/python2.7/site-packages/gunicorn/app/wsgiapp.py", line 65, in load
    return self.load_wsgiapp()
  File "/var/www/html/env/local/lib/python2.7/site-packages/gunicorn/app/wsgiapp.py", line 52, in load_wsgiapp
    return util.import_app(self.app_uri)
  File "/var/www/html/env/local/lib/python2.7/site-packages/gunicorn/util.py", line 352, in import_app
    __import__(module)
  File "/var/www/html/c3car/wsgi.py", line 1, in <module>
    from app import app
  File "/var/www/html/c3car/app.py", line 7, in <module>
    from pytz import timezone
ImportError: No module named pytz
[2018-03-10 13:07:31 +0000] [390] [INFO] Worker exiting (pid: 390)
[2018-03-10 13:07:31 +0000] [391] [ERROR] Exception in worker process
Traceback (most recent call last):
  File "/var/www/html/env/local/lib/python2.7/site-packages/gunicorn/arbiter.py", line 578, in spawn_worker
    worker.init_process()
  File "/var/www/html/env/local/lib/python2.7/site-packages/gunicorn/workers/base.py", line 126, in init_process
    self.load_wsgi()
  File "/var/www/html/env/local/lib/python2.7/site-packages/gunicorn/workers/base.py", line 135, in load_wsgi
    self.wsgi = self.app.wsgi()
  File "/var/www/html/env/local/lib/python2.7/site-packages/gunicorn/app/base.py", line 67, in wsgi
    self.callable = self.load()
  File "/var/www/html/env/local/lib/python2.7/site-packages/gunicorn/app/wsgiapp.py", line 65, in load
    return self.load_wsgiapp()
  File "/var/www/html/env/local/lib/python2.7/site-packages/gunicorn/app/wsgiapp.py", line 52, in load_wsgiapp
    return util.import_app(self.app_uri)
  File "/var/www/html/env/local/lib/python2.7/site-packages/gunicorn/util.py", line 352, in import_app
    __import__(module)
  File "/var/www/html/c3car/wsgi.py", line 1, in <module>
    from app import app
  File "/var/www/html/c3car/app.py", line 7, in <module>
    from pytz import timezone
ImportError: No module named pytz
[2018-03-10 13:07:31 +0000] [391] [INFO] Worker exiting (pid: 391)
[2018-03-10 13:07:31 +0000] [389] [INFO] Worker exiting (pid: 389)
[2018-03-10 13:12:22 +0000] [570] [INFO] Starting gunicorn 19.7.1
[2018-03-10 13:12:22 +0000] [570] [INFO] Listening at: unix:carwash.sock (570)
[2018-03-10 13:12:22 +0000] [570] [INFO] Using worker: sync
[2018-03-10 13:12:22 +0000] [573] [INFO] Booting worker with pid: 573
[2018-03-10 13:12:23 +0000] [574] [INFO] Booting worker with pid: 574
[2018-03-10 13:12:23 +0000] [575] [INFO] Booting worker with pid: 575
[2018-03-10 13:12:25 +0000] [573] [ERROR] Exception in worker process
Traceback (most recent call last):
  File "/var/www/html/env/local/lib/python2.7/site-packages/gunicorn/arbiter.py", line 578, in spawn_worker
    worker.init_process()
  File "/var/www/html/env/local/lib/python2.7/site-packages/gunicorn/workers/base.py", line 126, in init_process
    self.load_wsgi()
  File "/var/www/html/env/local/lib/python2.7/site-packages/gunicorn/workers/base.py", line 135, in load_wsgi
    self.wsgi = self.app.wsgi()
  File "/var/www/html/env/local/lib/python2.7/site-packages/gunicorn/app/base.py", line 67, in wsgi
    self.callable = self.load()
  File "/var/www/html/env/local/lib/python2.7/site-packages/gunicorn/app/wsgiapp.py", line 65, in load
    return self.load_wsgiapp()
  File "/var/www/html/env/local/lib/python2.7/site-packages/gunicorn/app/wsgiapp.py", line 52, in load_wsgiapp
    return util.import_app(self.app_uri)
  File "/var/www/html/env/local/lib/python2.7/site-packages/gunicorn/util.py", line 352, in import_app
    __import__(module)
  File "/var/www/html/c3car/wsgi.py", line 1, in <module>
    from app import app
  File "/var/www/html/c3car/app.py", line 7, in <module>
    from pytz import timezone
ImportError: No module named pytz
[2018-03-10 13:12:25 +0000] [573] [INFO] Worker exiting (pid: 573)
[2018-03-10 13:12:25 +0000] [574] [ERROR] Exception in worker process
Traceback (most recent call last):
  File "/var/www/html/env/local/lib/python2.7/site-packages/gunicorn/arbiter.py", line 578, in spawn_worker
    worker.init_process()
  File "/var/www/html/env/local/lib/python2.7/site-packages/gunicorn/workers/base.py", line 126, in init_process
    self.load_wsgi()
  File "/var/www/html/env/local/lib/python2.7/site-packages/gunicorn/workers/base.py", line 135, in load_wsgi
    self.wsgi = self.app.wsgi()
  File "/var/www/html/env/local/lib/python2.7/site-packages/gunicorn/app/base.py", line 67, in wsgi
    self.callable = self.load()
  File "/var/www/html/env/local/lib/python2.7/site-packages/gunicorn/app/wsgiapp.py", line 65, in load
    return self.load_wsgiapp()
  File "/var/www/html/env/local/lib/python2.7/site-packages/gunicorn/app/wsgiapp.py", line 52, in load_wsgiapp
    return util.import_app(self.app_uri)
  File "/var/www/html/env/local/lib/python2.7/site-packages/gunicorn/util.py", line 352, in import_app
    __import__(module)
  File "/var/www/html/c3car/wsgi.py", line 1, in <module>
    from app import app
  File "/var/www/html/c3car/app.py", line 7, in <module>
    from pytz import timezone
ImportError: No module named pytz
[2018-03-10 13:12:25 +0000] [574] [INFO] Worker exiting (pid: 574)
[2018-03-10 13:12:25 +0000] [575] [ERROR] Exception in worker process
Traceback (most recent call last):
  File "/var/www/html/env/local/lib/python2.7/site-packages/gunicorn/arbiter.py", line 578, in spawn_worker
    worker.init_process()
  File "/var/www/html/env/local/lib/python2.7/site-packages/gunicorn/workers/base.py", line 126, in init_process
    self.load_wsgi()
  File "/var/www/html/env/local/lib/python2.7/site-packages/gunicorn/workers/base.py", line 135, in load_wsgi
    self.wsgi = self.app.wsgi()
  File "/var/www/html/env/local/lib/python2.7/site-packages/gunicorn/app/base.py", line 67, in wsgi
    self.callable = self.load()
  File "/var/www/html/env/local/lib/python2.7/site-packages/gunicorn/app/wsgiapp.py", line 65, in load
    return self.load_wsgiapp()
  File "/var/www/html/env/local/lib/python2.7/site-packages/gunicorn/app/wsgiapp.py", line 52, in load_wsgiapp
    return util.import_app(self.app_uri)
  File "/var/www/html/env/local/lib/python2.7/site-packages/gunicorn/util.py", line 352, in import_app
    __import__(module)
  File "/var/www/html/c3car/wsgi.py", line 1, in <module>
    from app import app
  File "/var/www/html/c3car/app.py", line 7, in <module>
    from pytz import timezone
ImportError: No module named pytz
[2018-03-10 13:12:25 +0000] [575] [INFO] Worker exiting (pid: 575)
[2018-03-10 13:12:25 +0000] [570] [INFO] Shutting down: Master
[2018-03-10 13:12:25 +0000] [570] [INFO] Reason: Worker failed to boot.
[2018-03-10 13:13:34 +0000] [616] [INFO] Starting gunicorn 19.7.1
[2018-03-10 13:13:34 +0000] [616] [INFO] Listening at: unix:carwash.sock (616)
[2018-03-10 13:13:34 +0000] [616] [INFO] Using worker: sync
[2018-03-10 13:13:34 +0000] [619] [INFO] Booting worker with pid: 619
[2018-03-10 13:13:34 +0000] [620] [INFO] Booting worker with pid: 620
[2018-03-10 13:13:34 +0000] [621] [INFO] Booting worker with pid: 621
[2018-03-10 13:13:36 +0000] [619] [ERROR] Exception in worker process
Traceback (most recent call last):
  File "/var/www/html/env/local/lib/python2.7/site-packages/gunicorn/arbiter.py", line 578, in spawn_worker
    worker.init_process()
  File "/var/www/html/env/local/lib/python2.7/site-packages/gunicorn/workers/base.py", line 126, in init_process
    self.load_wsgi()
  File "/var/www/html/env/local/lib/python2.7/site-packages/gunicorn/workers/base.py", line 135, in load_wsgi
    self.wsgi = self.app.wsgi()
  File "/var/www/html/env/local/lib/python2.7/site-packages/gunicorn/app/base.py", line 67, in wsgi
    self.callable = self.load()
  File "/var/www/html/env/local/lib/python2.7/site-packages/gunicorn/app/wsgiapp.py", line 65, in load
    return self.load_wsgiapp()
  File "/var/www/html/env/local/lib/python2.7/site-packages/gunicorn/app/wsgiapp.py", line 52, in load_wsgiapp
    return util.import_app(self.app_uri)
  File "/var/www/html/env/local/lib/python2.7/site-packages/gunicorn/util.py", line 352, in import_app
    __import__(module)
  File "/var/www/html/c3car/wsgi.py", line 1, in <module>
    from app import app
  File "/var/www/html/c3car/app.py", line 7, in <module>
    from pytz import timezone
ImportError: No module named pytz
[2018-03-10 13:13:36 +0000] [619] [INFO] Worker exiting (pid: 619)
[2018-03-10 13:13:36 +0000] [620] [ERROR] Exception in worker process
Traceback (most recent call last):
  File "/var/www/html/env/local/lib/python2.7/site-packages/gunicorn/arbiter.py", line 578, in spawn_worker
    worker.init_process()
  File "/var/www/html/env/local/lib/python2.7/site-packages/gunicorn/workers/base.py", line 126, in init_process
    self.load_wsgi()
  File "/var/www/html/env/local/lib/python2.7/site-packages/gunicorn/workers/base.py", line 135, in load_wsgi
    self.wsgi = self.app.wsgi()
  File "/var/www/html/env/local/lib/python2.7/site-packages/gunicorn/app/base.py", line 67, in wsgi
    self.callable = self.load()
  File "/var/www/html/env/local/lib/python2.7/site-packages/gunicorn/app/wsgiapp.py", line 65, in load
    return self.load_wsgiapp()
  File "/var/www/html/env/local/lib/python2.7/site-packages/gunicorn/app/wsgiapp.py", line 52, in load_wsgiapp
    return util.import_app(self.app_uri)
  File "/var/www/html/env/local/lib/python2.7/site-packages/gunicorn/util.py", line 352, in import_app
    __import__(module)
  File "/var/www/html/c3car/wsgi.py", line 1, in <module>
    from app import app
  File "/var/www/html/c3car/app.py", line 7, in <module>
    from pytz import timezone
ImportError: No module named pytz
[2018-03-10 13:13:36 +0000] [620] [INFO] Worker exiting (pid: 620)
[2018-03-10 13:13:37 +0000] [621] [ERROR] Exception in worker process
Traceback (most recent call last):
  File "/var/www/html/env/local/lib/python2.7/site-packages/gunicorn/arbiter.py", line 578, in spawn_worker
    worker.init_process()
  File "/var/www/html/env/local/lib/python2.7/site-packages/gunicorn/workers/base.py", line 126, in init_process
    self.load_wsgi()
  File "/var/www/html/env/local/lib/python2.7/site-packages/gunicorn/workers/base.py", line 135, in load_wsgi
    self.wsgi = self.app.wsgi()
  File "/var/www/html/env/local/lib/python2.7/site-packages/gunicorn/app/base.py", line 67, in wsgi
    self.callable = self.load()
  File "/var/www/html/env/local/lib/python2.7/site-packages/gunicorn/app/wsgiapp.py", line 65, in load
    return self.load_wsgiapp()
  File "/var/www/html/env/local/lib/python2.7/site-packages/gunicorn/app/wsgiapp.py", line 52, in load_wsgiapp
    return util.import_app(self.app_uri)
  File "/var/www/html/env/local/lib/python2.7/site-packages/gunicorn/util.py", line 352, in import_app
    __import__(module)
  File "/var/www/html/c3car/wsgi.py", line 1, in <module>
    from app import app
  File "/var/www/html/c3car/app.py", line 7, in <module>
    from pytz import timezone
ImportError: No module named pytz
[2018-03-10 13:13:37 +0000] [621] [INFO] Worker exiting (pid: 621)
[2018-03-10 13:13:37 +0000] [616] [INFO] Shutting down: Master
[2018-03-10 13:13:37 +0000] [616] [INFO] Reason: Worker failed to boot.
[2018-03-10 13:14:11 +0000] [646] [INFO] Starting gunicorn 19.7.1
[2018-03-10 13:14:11 +0000] [646] [INFO] Listening at: unix:carwash.sock (646)
[2018-03-10 13:14:11 +0000] [646] [INFO] Using worker: sync
[2018-03-10 13:14:11 +0000] [649] [INFO] Booting worker with pid: 649
[2018-03-10 13:14:12 +0000] [650] [INFO] Booting worker with pid: 650
[2018-03-10 13:14:12 +0000] [651] [INFO] Booting worker with pid: 651
[2018-03-10 13:14:14 +0000] [649] [ERROR] Exception in worker process
Traceback (most recent call last):
  File "/var/www/html/env/local/lib/python2.7/site-packages/gunicorn/arbiter.py", line 578, in spawn_worker
    worker.init_process()
  File "/var/www/html/env/local/lib/python2.7/site-packages/gunicorn/workers/base.py", line 126, in init_process
    self.load_wsgi()
  File "/var/www/html/env/local/lib/python2.7/site-packages/gunicorn/workers/base.py", line 135, in load_wsgi
    self.wsgi = self.app.wsgi()
  File "/var/www/html/env/local/lib/python2.7/site-packages/gunicorn/app/base.py", line 67, in wsgi
    self.callable = self.load()
  File "/var/www/html/env/local/lib/python2.7/site-packages/gunicorn/app/wsgiapp.py", line 65, in load
    return self.load_wsgiapp()
  File "/var/www/html/env/local/lib/python2.7/site-packages/gunicorn/app/wsgiapp.py", line 52, in load_wsgiapp
    return util.import_app(self.app_uri)
  File "/var/www/html/env/local/lib/python2.7/site-packages/gunicorn/util.py", line 352, in import_app
    __import__(module)
  File "/var/www/html/c3car/wsgi.py", line 1, in <module>
    from app import app
  File "/var/www/html/c3car/app.py", line 7, in <module>
    from pytz import timezone
ImportError: No module named pytz
[2018-03-10 13:14:14 +0000] [649] [INFO] Worker exiting (pid: 649)
[2018-03-10 13:14:14 +0000] [650] [ERROR] Exception in worker process
Traceback (most recent call last):
  File "/var/www/html/env/local/lib/python2.7/site-packages/gunicorn/arbiter.py", line 578, in spawn_worker
    worker.init_process()
  File "/var/www/html/env/local/lib/python2.7/site-packages/gunicorn/workers/base.py", line 126, in init_process
    self.load_wsgi()
  File "/var/www/html/env/local/lib/python2.7/site-packages/gunicorn/workers/base.py", line 135, in load_wsgi
    self.wsgi = self.app.wsgi()
  File "/var/www/html/env/local/lib/python2.7/site-packages/gunicorn/app/base.py", line 67, in wsgi
    self.callable = self.load()
  File "/var/www/html/env/local/lib/python2.7/site-packages/gunicorn/app/wsgiapp.py", line 65, in load
    return self.load_wsgiapp()
  File "/var/www/html/env/local/lib/python2.7/site-packages/gunicorn/app/wsgiapp.py", line 52, in load_wsgiapp
    return util.import_app(self.app_uri)
  File "/var/www/html/env/local/lib/python2.7/site-packages/gunicorn/util.py", line 352, in import_app
    __import__(module)
  File "/var/www/html/c3car/wsgi.py", line 1, in <module>
    from app import app
  File "/var/www/html/c3car/app.py", line 7, in <module>
    from pytz import timezone
ImportError: No module named pytz
[2018-03-10 13:14:14 +0000] [650] [INFO] Worker exiting (pid: 650)
[2018-03-10 13:14:14 +0000] [651] [ERROR] Exception in worker process
Traceback (most recent call last):
  File "/var/www/html/env/local/lib/python2.7/site-packages/gunicorn/arbiter.py", line 578, in spawn_worker
    worker.init_process()
  File "/var/www/html/env/local/lib/python2.7/site-packages/gunicorn/workers/base.py", line 126, in init_process
    self.load_wsgi()
  File "/var/www/html/env/local/lib/python2.7/site-packages/gunicorn/workers/base.py", line 135, in load_wsgi
    self.wsgi = self.app.wsgi()
  File "/var/www/html/env/local/lib/python2.7/site-packages/gunicorn/app/base.py", line 67, in wsgi
    self.callable = self.load()
  File "/var/www/html/env/local/lib/python2.7/site-packages/gunicorn/app/wsgiapp.py", line 65, in load
    return self.load_wsgiapp()
  File "/var/www/html/env/local/lib/python2.7/site-packages/gunicorn/app/wsgiapp.py", line 52, in load_wsgiapp
    return util.import_app(self.app_uri)
  File "/var/www/html/env/local/lib/python2.7/site-packages/gunicorn/util.py", line 352, in import_app
    __import__(module)
  File "/var/www/html/c3car/wsgi.py", line 1, in <module>
    from app import app
  File "/var/www/html/c3car/app.py", line 7, in <module>
    from pytz import timezone
ImportError: No module named pytz
[2018-03-10 13:14:14 +0000] [651] [INFO] Worker exiting (pid: 651)
[2018-03-10 13:14:14 +0000] [646] [INFO] Shutting down: Master
[2018-03-10 13:14:14 +0000] [646] [INFO] Reason: Worker failed to boot.
[2018-03-10 13:20:34 +0000] [690] [INFO] Starting gunicorn 19.7.1
[2018-03-10 13:20:34 +0000] [690] [INFO] Listening at: unix:carwash.sock (690)
[2018-03-10 13:20:34 +0000] [690] [INFO] Using worker: sync
[2018-03-10 13:20:34 +0000] [693] [INFO] Booting worker with pid: 693
[2018-03-10 13:20:34 +0000] [694] [INFO] Booting worker with pid: 694
[2018-03-10 13:20:34 +0000] [695] [INFO] Booting worker with pid: 695
[2018-03-10 13:20:36 +0000] [693] [ERROR] Exception in worker process
Traceback (most recent call last):
  File "/var/www/html/env/local/lib/python2.7/site-packages/gunicorn/arbiter.py", line 578, in spawn_worker
    worker.init_process()
  File "/var/www/html/env/local/lib/python2.7/site-packages/gunicorn/workers/base.py", line 126, in init_process
    self.load_wsgi()
  File "/var/www/html/env/local/lib/python2.7/site-packages/gunicorn/workers/base.py", line 135, in load_wsgi
    self.wsgi = self.app.wsgi()
  File "/var/www/html/env/local/lib/python2.7/site-packages/gunicorn/app/base.py", line 67, in wsgi
    self.callable = self.load()
  File "/var/www/html/env/local/lib/python2.7/site-packages/gunicorn/app/wsgiapp.py", line 65, in load
    return self.load_wsgiapp()
  File "/var/www/html/env/local/lib/python2.7/site-packages/gunicorn/app/wsgiapp.py", line 52, in load_wsgiapp
    return util.import_app(self.app_uri)
  File "/var/www/html/env/local/lib/python2.7/site-packages/gunicorn/util.py", line 352, in import_app
    __import__(module)
  File "/var/www/html/c3car/wsgi.py", line 1, in <module>
    from app import app
  File "/var/www/html/c3car/app.py", line 7, in <module>
    from pytz import timezone
ImportError: No module named pytz
[2018-03-10 13:20:36 +0000] [693] [INFO] Worker exiting (pid: 693)
[2018-03-10 13:20:36 +0000] [694] [ERROR] Exception in worker process
Traceback (most recent call last):
  File "/var/www/html/env/local/lib/python2.7/site-packages/gunicorn/arbiter.py", line 578, in spawn_worker
    worker.init_process()
  File "/var/www/html/env/local/lib/python2.7/site-packages/gunicorn/workers/base.py", line 126, in init_process
    self.load_wsgi()
  File "/var/www/html/env/local/lib/python2.7/site-packages/gunicorn/workers/base.py", line 135, in load_wsgi
    self.wsgi = self.app.wsgi()
  File "/var/www/html/env/local/lib/python2.7/site-packages/gunicorn/app/base.py", line 67, in wsgi
    self.callable = self.load()
  File "/var/www/html/env/local/lib/python2.7/site-packages/gunicorn/app/wsgiapp.py", line 65, in load
    return self.load_wsgiapp()
  File "/var/www/html/env/local/lib/python2.7/site-packages/gunicorn/app/wsgiapp.py", line 52, in load_wsgiapp
    return util.import_app(self.app_uri)
  File "/var/www/html/env/local/lib/python2.7/site-packages/gunicorn/util.py", line 352, in import_app
    __import__(module)
  File "/var/www/html/c3car/wsgi.py", line 1, in <module>
    from app import app
  File "/var/www/html/c3car/app.py", line 7, in <module>
    from pytz import timezone
ImportError: No module named pytz
[2018-03-10 13:20:36 +0000] [694] [INFO] Worker exiting (pid: 694)
[2018-03-10 13:20:36 +0000] [695] [ERROR] Exception in worker process
Traceback (most recent call last):
  File "/var/www/html/env/local/lib/python2.7/site-packages/gunicorn/arbiter.py", line 578, in spawn_worker
    worker.init_process()
  File "/var/www/html/env/local/lib/python2.7/site-packages/gunicorn/workers/base.py", line 126, in init_process
    self.load_wsgi()
  File "/var/www/html/env/local/lib/python2.7/site-packages/gunicorn/workers/base.py", line 135, in load_wsgi
    self.wsgi = self.app.wsgi()
  File "/var/www/html/env/local/lib/python2.7/site-packages/gunicorn/app/base.py", line 67, in wsgi
    self.callable = self.load()
  File "/var/www/html/env/local/lib/python2.7/site-packages/gunicorn/app/wsgiapp.py", line 65, in load
    return self.load_wsgiapp()
  File "/var/www/html/env/local/lib/python2.7/site-packages/gunicorn/app/wsgiapp.py", line 52, in load_wsgiapp
    return util.import_app(self.app_uri)
  File "/var/www/html/env/local/lib/python2.7/site-packages/gunicorn/util.py", line 352, in import_app
    __import__(module)
  File "/var/www/html/c3car/wsgi.py", line 1, in <module>
    from app import app
  File "/var/www/html/c3car/app.py", line 7, in <module>
    from pytz import timezone
ImportError: No module named pytz
[2018-03-10 13:20:36 +0000] [695] [INFO] Worker exiting (pid: 695)
[2018-03-10 13:20:36 +0000] [690] [INFO] Shutting down: Master
[2018-03-10 13:20:36 +0000] [690] [INFO] Reason: Worker failed to boot.
[2018-03-10 13:20:44 +0000] [703] [INFO] Starting gunicorn 19.7.1
[2018-03-10 13:20:44 +0000] [703] [INFO] Listening at: unix:carwash.sock (703)
[2018-03-10 13:20:44 +0000] [703] [INFO] Using worker: sync
[2018-03-10 13:20:44 +0000] [706] [INFO] Booting worker with pid: 706
[2018-03-10 13:20:44 +0000] [707] [INFO] Booting worker with pid: 707
[2018-03-10 13:20:44 +0000] [708] [INFO] Booting worker with pid: 708
[2018-03-10 13:20:46 +0000] [706] [ERROR] Exception in worker process
Traceback (most recent call last):
  File "/var/www/html/env/local/lib/python2.7/site-packages/gunicorn/arbiter.py", line 578, in spawn_worker
    worker.init_process()
  File "/var/www/html/env/local/lib/python2.7/site-packages/gunicorn/workers/base.py", line 126, in init_process
    self.load_wsgi()
  File "/var/www/html/env/local/lib/python2.7/site-packages/gunicorn/workers/base.py", line 135, in load_wsgi
    self.wsgi = self.app.wsgi()
  File "/var/www/html/env/local/lib/python2.7/site-packages/gunicorn/app/base.py", line 67, in wsgi
    self.callable = self.load()
  File "/var/www/html/env/local/lib/python2.7/site-packages/gunicorn/app/wsgiapp.py", line 65, in load
    return self.load_wsgiapp()
  File "/var/www/html/env/local/lib/python2.7/site-packages/gunicorn/app/wsgiapp.py", line 52, in load_wsgiapp
    return util.import_app(self.app_uri)
  File "/var/www/html/env/local/lib/python2.7/site-packages/gunicorn/util.py", line 352, in import_app
    __import__(module)
  File "/var/www/html/c3car/wsgi.py", line 1, in <module>
    from app import app
  File "/var/www/html/c3car/app.py", line 7, in <module>
    from pytz import timezone
ImportError: No module named pytz
[2018-03-10 13:20:46 +0000] [706] [INFO] Worker exiting (pid: 706)
[2018-03-10 13:20:46 +0000] [707] [ERROR] Exception in worker process
Traceback (most recent call last):
  File "/var/www/html/env/local/lib/python2.7/site-packages/gunicorn/arbiter.py", line 578, in spawn_worker
    worker.init_process()
  File "/var/www/html/env/local/lib/python2.7/site-packages/gunicorn/workers/base.py", line 126, in init_process
    self.load_wsgi()
  File "/var/www/html/env/local/lib/python2.7/site-packages/gunicorn/workers/base.py", line 135, in load_wsgi
    self.wsgi = self.app.wsgi()
  File "/var/www/html/env/local/lib/python2.7/site-packages/gunicorn/app/base.py", line 67, in wsgi
    self.callable = self.load()
  File "/var/www/html/env/local/lib/python2.7/site-packages/gunicorn/app/wsgiapp.py", line 65, in load
    return self.load_wsgiapp()
  File "/var/www/html/env/local/lib/python2.7/site-packages/gunicorn/app/wsgiapp.py", line 52, in load_wsgiapp
    return util.import_app(self.app_uri)
  File "/var/www/html/env/local/lib/python2.7/site-packages/gunicorn/util.py", line 352, in import_app
    __import__(module)
  File "/var/www/html/c3car/wsgi.py", line 1, in <module>
    from app import app
  File "/var/www/html/c3car/app.py", line 7, in <module>
    from pytz import timezone
ImportError: No module named pytz
[2018-03-10 13:20:46 +0000] [707] [INFO] Worker exiting (pid: 707)
[2018-03-10 13:20:47 +0000] [708] [ERROR] Exception in worker process
Traceback (most recent call last):
  File "/var/www/html/env/local/lib/python2.7/site-packages/gunicorn/arbiter.py", line 578, in spawn_worker
    worker.init_process()
  File "/var/www/html/env/local/lib/python2.7/site-packages/gunicorn/workers/base.py", line 126, in init_process
    self.load_wsgi()
  File "/var/www/html/env/local/lib/python2.7/site-packages/gunicorn/workers/base.py", line 135, in load_wsgi
    self.wsgi = self.app.wsgi()
  File "/var/www/html/env/local/lib/python2.7/site-packages/gunicorn/app/base.py", line 67, in wsgi
    self.callable = self.load()
  File "/var/www/html/env/local/lib/python2.7/site-packages/gunicorn/app/wsgiapp.py", line 65, in load
    return self.load_wsgiapp()
  File "/var/www/html/env/local/lib/python2.7/site-packages/gunicorn/app/wsgiapp.py", line 52, in load_wsgiapp
    return util.import_app(self.app_uri)
  File "/var/www/html/env/local/lib/python2.7/site-packages/gunicorn/util.py", line 352, in import_app
    __import__(module)
  File "/var/www/html/c3car/wsgi.py", line 1, in <module>
    from app import app
  File "/var/www/html/c3car/app.py", line 7, in <module>
    from pytz import timezone
ImportError: No module named pytz
[2018-03-10 13:20:47 +0000] [708] [INFO] Worker exiting (pid: 708)
[2018-03-10 13:20:47 +0000] [703] [INFO] Shutting down: Master
[2018-03-10 13:20:47 +0000] [703] [INFO] Reason: Worker failed to boot.
